Workbook
Name ManualWindDirection: WINTEM!$J$21
Name Vz_15: PERFORMANCE!$E$10
Name Fb: PERFORMANCE!$E$8
Name AverageWindDirection: WINTEM!$G$21
Name SpeedUnit: PERFORMANCE!$E$7
Name DInit: PERFORMANCE!$D$43
Name Zpo: PERFORMANCE!$D$46
Name FF_Procedures: PERFORMANCE!$H$71
Name TOW: PERFORMANCE!$E$16
Name DénDd: PERFORMANCE!$D$39
Name VzCorrZ: DR400120_PERFORMANCE!$C$73
Name ZRéf: PERFORMANCE!$H$18
Name VP3K: CTLS_FF!$D$24:$D$27
Name QFU: PERFORMANCE!$H$15
Name DR400_DaCorr: DR400120_PERFORMANCE!$D$113
Name VP7K: CTLS_FF!$D$40:$D$43
Name Dd: PERFORMANCE!$E$30
Name Dw: PERFORMANCE!$H$6
Name Etape2: CARBURANT!$B$25
Name VP10K: CTLS_FF!$D$52:$D$55
Name FF3K: CTLS_FF!$E$24:$E$27
Name CTLS_TOW: PERFORMANCE!$C$16
Name FF8K: CTLS_FF!$E$44:$E$47
Name Zo: PERFORMANCE!$C$22
Name Zd: PERFORMANCE!$K$5
Name Zp: PERFORMANCE!$K$4
Name Do: PERFORMANCE!$C$21
Name TODA: PERFORMANCE!$H$17
Name Veff: PERFORMANCE!$H$8
Name Hv_0: PERFORMANCE!$E$13
Name Da: PERFORMANCE!$E$32
Name VP5K: CTLS_FF!$D$32:$D$35
Name fplPath: fplAlign!$A$1
Name FF9K: CTLS_FF!$E$48:$E$51
Name FuelMax: PERFORMANCE!$E$14
Name Slope: PERFORMANCE!$K$18
Name GradCont: PERFORMANCE!$D$41
Name CTLS_LW: PERFORMANCE!$C$18
Name VP12K: CTLS_FF!$D$56:$D$59
Name Dra: PERFORMANCE!$E$31
Name Vw: PERFORMANCE!$H$7
Name FF5K: CTLS_FF!$E$32:$E$35
Name FF7K: CTLS_FF!$E$40:$E$43
Name ManualWindSpeed: WINTEM!$J$20
Name CTLS_DrdCorr: 'CTLS-LSA_PERFORMANCE'!$H$59
Name CTLS_DaCorr: 'CTLS-LSA_PERFORMANCE'!$K$59
Name FF6K: CTLS_FF!$E$36:$E$39
Name GradInit: PERFORMANCE!$D$40
Name QNH: PERFORMANCE!$H$4
Name SurfType: PERFORMANCE!$H$13
Name VP8K: CTLS_FF!$D$44:$D$47
Name Zt: PERFORMANCE!$H$12
Name WindMode: WINTEM!$J$15
Name CTLS_DraCorr: 'CTLS-LSA_PERFORMANCE'!$J$59
Name Drd: PERFORMANCE!$E$29
Name TORA: PERFORMANCE!$H$16
Name DR400_LW: PERFORMANCE!$D$18
Name FF4K: CTLS_FF!$E$28:$E$31
Name OAT: PERFORMANCE!$H$3
Name SurfEtat: PERFORMANCE!$H$14

Sheet READ ME !
B2: Top + estimée - Route - Altitude - Moteur - Essence - Radio | I2: H E | K2: FREQUENCE | P2: Top + estimée - Route - Altitude - Moteur - Essence - Radio | W2: H E | Y2: FREQUENCE
B3: Rm ° | D3: D nm | E3: Z ft | G3: T min | J3: H R | K3: REPORT | P3: Rm ° | R3: D nm | S3: Z ft | U3: T min | X3: H R | Y3: REPORT
C4: Cm ° | D4: Vi kts | F4: MSA ft | H4: Tw/ETA | I4: --- | K4: LES MUREAUX | Q4: Cm ° | R4: Vi kts | T4: MSA ft | V4: Tw/ETA
B5: 252 | D5: 6 | E5: 1000 | G5: 3.6 | K5: LFXU | M5: 122.955 | P5: 62 | R5: 8.8 | S5: 1400 | U5: 5.28 | Y5: MEZEROL
C6: 254.37336 | D6: 97.839799 | F6: 1400 | H6: 4 (52) | Q6: 58.122763 | R6: 97.20576 | T6: 1500 | V6: 5 (5)
B7: 222 | D7: 3.1 | E7: 1400 | G7: 1.86 | K7: SW | Y7: LFXU
C8: 228.49619 | D8: 97.20576 | F8: 1300 | H8: 2 (48) | K8: LE BOURGET Info
B9: 189 | D9: 8.2 | E9: 1900 | G9: 4.92 | K9: MEZEROL | M9: 123.835
C10: 198.00401 | D10: 96.424674 | F10: 1300 | H10: 5 (46)
B11: 189 | D11: 11 | E11: 1900 | G11: 6.6 | K11: N12
C12: 198.00401 | D12: 96.424674 | F12: 1400 | H12: 7 (41) | K12: CHARTRES
B13: 206 | D13: 11 | E13: 1900 | G13: 6.6 | K13: EPR | M13: 119.205
C14: 214.04433 | D14: 96.424674 | F14: 1300 | H14: 7 (34) | K14: LE BOURGET Approche
B15: 312 | D15: 2.8 | E15: 1900 | G15: 1.68 | K15: LFOR | M15: 118.8
C16: 305.50381 | D16: 96.424674 | F16: 1300 | H16: 2 (27)
B17: 340 | D17: 14 | E17: 1900 | G17: 8.4 | K17: N154
C18: 331.19867 | D18: 96.424674 | F18: 1600 | H18: 9 (25) | K18: DREUX
B19: 78 | D19: 2.8 | E19: 1900 | G19: 1.68 | K19: LFON | M19: 118.205
C20: 76.565765 | D20: 96.424674 | F20: 1400 | H20: 1 (16)
B21: 42 | D21: 18 | E21: 1900 | G21: 10.8 | K21: MEZIER
C22: 35.503813 | D22: 96.424674 | F22: 1300 | H22: 10 (14)
K23: MEZEROL
D25: hh:mm | E25: L | I25: DEP (E/R) | L25: ARR | P25: QNH | Q25: 1015 | S25: Vw | T25: 16 | U25: kts | V25: Xm | W25: 9.6 | X25: deg | Y25: AUTRES FREQUENCES
B26: PROC DEP | D26: 0.0069444444 | E26: 2.2133559 | G26: DATE | I26: 45109 | P26: OAT | Q26: 18 | R26: °C | S26: Dw | T26: 267 | U26: deg | V26: Fb | W26: 0.6 | Y26: LE BOURGET Approche | AB26: 118.8
B27: ETAPES | D27: 0.036346018 | E27: 11.584321 | G27: HEURE | I27: 0.5 | Q27: 100 | R27: ft | S27: FF | T27: 13.280135 | U27: L/h | V27: D | W27: 85.7 | X27: nm
B28: PROC ARR | D28: 0.0069444444 | E28: 2.2133559 | G28: HOBBS | N28: h,m | Y28: PONTOISE ATIS | AB28: 124.125
B29: RES. ROUTE | D29: 0.013888889 | E29: 4.4267117 | G29: CARBU (L) | I29: 60 | N29: L | P29: α | Q29: 0 | R29: 30 | S29: 45 | T29: 60 | U29: 90 | V29: deg
B30: RES. FINALE | D30: 0.020833333 | E30: 6.6400676 | G30: AUTONOMIE | I30: 0.15644845 | L30: hh:mm | P30: X° | Q30: 0 | R30: 4.8 | S30: 6.7882251 | T30: 8.3138439 | U30: 9.6 | V30: deg | Y30: GUARD | AB30: 121.5
B31: CARBU MINI | D31: 0.084957129 | E31: 27.077812 | G31: ARR. MOT. | I31: 0.65644845 | P31: Tc | Q31: 9.6 | R31: 8.3138439 | S31: 6.7882251 | T31: 4.8 | U31: 0 | V31: s/min
G32: ROLL / 50 ft | J32: 200 | K32: 370 | L32: 140 | M32: 360 | N32: m

Sheet fplAlign
A1: https://drive.google.com/open?id=1CD8gElm2eIWqvcc28HXxKBx5Kiu-HcaF&usp=drive_fs | B1: Identifiant | C1: Type
B2: LFXU | C2: AIRPORT
B3: XUSW | C3: USER WAYPOINT
B4: MEZER | C4: USER WAYPOINT
B5: ONEE | C5: USER WAYPOINT
B6: LFON | C6: AIRPORT

Sheet LOG
A1: pasca
B2: Top + estimée - Route - Altitude - Moteur - Essence - Radio | I2: H E | K2: FREQUENCE | P2: Top + estimée - Route - Altitude - Moteur - Essence - Radio | W2: H E | Y2: FREQUENCE
B3: Rm ° | D3: D nm | E3: Z ft | G3: T min | J3: H R | K3: REPORT | P3: Rm ° | R3: D nm | S3: Z ft | U3: T min | X3: H R | Y3: REPORT
C4: Cm ° | D4: ="Vi "&SpeedUnit -> Vi kn | F4: MSA/Tx | H4: Tw/Fuel | I4: --- | N4: LES MUREAUX | Q4: Cm ° | R4: ="Vi "&SpeedUnit -> Vi kn | T4: MSA ft | V4: Tw/Fuel
B5: ='CALCULS BRANCHES'!M2 -> 252 | D5: ='CALCULS BRANCHES'!F2 -> 6 | E5: =IF('CALCULS BRANCHES'!J2,CONCATENATE("FL",'CALCULS BRANCHES'!J2),'CALCULS BRANCHES'!I2) -> 1400 | G5: ='CALCULS BRANCHES'!AG2 -> 3.6 | K5: ='CALCULS BRANCHES'!A2 -> LFXU | M5: =IFERROR(VLOOKUP(N4,FREQUENCES!$A:$B,2,0),) -> 122.955 | P5: ='CALCULS BRANCHES'!M11 | R5: ='CALCULS BRANCHES'!F11 | S5: =IF('CALCULS BRANCHES'!J11,CONCATENATE("FL",'CALCULS BRANCHES'!J11),'CALCULS BRANCHES'!I11) | U5: ='CALCULS BRANCHES'!AG11 | Y5: ='CALCULS BRANCHES'!A11 | AA5: =IFERROR(VLOOKUP(AB4,FREQUENCES!$A:$B,2,0),)
C6: ='CALCULS BRANCHES'!AF2 -> 260.57931 | D6: =IF(COUNTIF('CALCULS BRANCHES'!B2,""),"",TEXT(ROUND(CONVERT('CALCULS BRANCHES'!Y2,"kn",SpeedUnit),0),"000")) -> 099 | F6: =IF('CALCULS BRANCHES'!J2,CONCATENATE("TA",'CALCULS BRANCHES'!Q2),'CALCULS BRANCHES'!K2) -> 1100 | H6: =IF(COUNTIF('CALCULS BRANCHES'!B2,""),,ROUND('CALCULS BRANCHES'!AH2,0)&" ("&'CALCULS BRANCHES'!AK2&")") -> 4 (1,44) | Q6: ='CALCULS BRANCHES'!AF11 | R6: =IF(COUNTIF('CALCULS BRANCHES'!B11,""),"",TEXT(ROUND(CONVERT('CALCULS BRANCHES'!Y11,"kn",SpeedUnit),0),"000")) | T6: =IF('CALCULS BRANCHES'!J11,IF('CALCULS BRANCHES'!I10,CONCATENATE("TA",'CALCULS BRANCHES'!Q11),CONCATENATE("TL",'CALCULS BRANCHES'!S11)),IF('CALCULS BRANCHES'!J10,CONCATENATE("TL",'CALCULS BRANCHES'!S11),'CALCULS BRANCHES'!K11)) | V6: =IF(COUNTIF('CALCULS BRANCHES'!B11,""),,ROUND('CALCULS BRANCHES'!AH11,0)&" ("&ROUND('CALCULS BRANCHES'!AK11,2)&")")
B7: ='CALCULS BRANCHES'!M3 -> 221 | D7: ='CALCULS BRANCHES'!F3 -> 3.1 | E7: =IF('CALCULS BRANCHES'!J3,CONCATENATE("FL",'CALCULS BRANCHES'!J3),'CALCULS BRANCHES'!I3) -> 1400 | G7: ='CALCULS BRANCHES'!AG3 -> 1.86 | K7: ='CALCULS BRANCHES'!B2 -> PTSW | M7: =IFERROR(VLOOKUP(N6,FREQUENCES!$A:$B,2,0),) | P7: ='CALCULS BRANCHES'!M12 | R7: ='CALCULS BRANCHES'!F12 | S7: =IF('CALCULS BRANCHES'!J12,CONCATENATE("FL",'CALCULS BRANCHES'!J12),'CALCULS BRANCHES'!I12) | U7: ='CALCULS BRANCHES'!AG12 | Y7: ='CALCULS BRANCHES'!B11 | AA7: =IFERROR(VLOOKUP(AB6,FREQUENCES!$A:$B,2,0),)
C8: ='CALCULS BRANCHES'!AF3 -> 228.81334 | D8: =IF(COUNTIF('CALCULS BRANCHES'!B3,""),"",TEXT(ROUND(CONVERT('CALCULS BRANCHES'!Y3,"kn",SpeedUnit),0),"000")) -> 099 | F8: =IF('CALCULS BRANCHES'!J3,IF('CALCULS BRANCHES'!I2,CONCATENATE("TA",'CALCULS BRANCHES'!Q3),CONCATENATE("TL",'CALCULS BRANCHES'!S3)),IF('CALCULS BRANCHES'!J2,CONCATENATE("TL",'CALCULS BRANCHES'!S3),'CALCULS BRANCHES'!K3)) -> 1500 | H8: =IF(COUNTIF('CALCULS BRANCHES'!B3,""),,ROUND('CALCULS BRANCHES'!AH3,0)&" ("&'CALCULS BRANCHES'!AK3&")") -> 2 (1,39) | N8: LE BOURGET Info | Q8: ='CALCULS BRANCHES'!AF12 | R8: =IF(COUNTIF('CALCULS BRANCHES'!B12,""),"",TEXT(ROUND(CONVERT('CALCULS BRANCHES'!Y12,"kn",SpeedUnit),0),"000")) | T8: =IF('CALCULS BRANCHES'!J12,IF('CALCULS BRANCHES'!I11,CONCATENATE("TA",'CALCULS BRANCHES'!Q12),CONCATENATE("TL",'CALCULS BRANCHES'!S12)),IF('CALCULS BRANCHES'!J11,CONCATENATE("TL",'CALCULS BRANCHES'!S12),'CALCULS BRANCHES'!K12)) | V8: =IF(COUNTIF('CALCULS BRANCHES'!B12,""),,ROUND('CALCULS BRANCHES'!AH12,0)&" ("&ROUND('CALCULS BRANCHES'!AK12,2)&")")
B9: ='CALCULS BRANCHES'!M4 -> 189 | D9: ='CALCULS BRANCHES'!F4 -> 8.2 | E9: =IF('CALCULS BRANCHES'!J4,CONCATENATE("FL",'CALCULS BRANCHES'!J4),'CALCULS BRANCHES'!I4) -> 1400 | G9: ='CALCULS BRANCHES'!AG4 -> 4.92 | K9: ='CALCULS BRANCHES'!B3 -> MEZER | M9: =IFERROR(VLOOKUP(N8,FREQUENCES!$A:$B,2,0),) -> 123.835 | P9: ='CALCULS BRANCHES'!M13 | R9: ='CALCULS BRANCHES'!F13 | S9: =IF('CALCULS BRANCHES'!J13,CONCATENATE("FL",'CALCULS BRANCHES'!J13),'CALCULS BRANCHES'!I13) | U9: ='CALCULS BRANCHES'!AG13 | Y9: ='CALCULS BRANCHES'!B12 | AA9: =IFERROR(VLOOKUP(AB8,FREQUENCES!$A:$B,2,0),)
C10: ='CALCULS BRANCHES'!AF4 -> 193.68605 | D10: =IF(COUNTIF('CALCULS BRANCHES'!B4,""),"",TEXT(ROUND(CONVERT('CALCULS BRANCHES'!Y4,"kn",SpeedUnit),0),"000")) -> 099 | F10: =IF('CALCULS BRANCHES'!J4,IF('CALCULS BRANCHES'!I3,CONCATENATE("TA",'CALCULS BRANCHES'!Q4),CONCATENATE("TL",'CALCULS BRANCHES'!S4)),IF('CALCULS BRANCHES'!J3,CONCATENATE("TL",'CALCULS BRANCHES'!S4),'CALCULS BRANCHES'!K4)) -> 1400 | H10: =IF(COUNTIF('CALCULS BRANCHES'!B4,""),,ROUND('CALCULS BRANCHES'!AH4,0)&" ("&'CALCULS BRANCHES'!AK4&")") -> 4 (1,28) | Q10: ='CALCULS BRANCHES'!AF13 | R10: =IF(COUNTIF('CALCULS BRANCHES'!B13,""),"",TEXT(ROUND(CONVERT('CALCULS BRANCHES'!Y13,"kn",SpeedUnit),0),"000")) | T10: =IF('CALCULS BRANCHES'!J13,IF('CALCULS BRANCHES'!I12,CONCATENATE("TA",'CALCULS BRANCHES'!Q13),CONCATENATE("TL",'CALCULS BRANCHES'!S13)),IF('CALCULS BRANCHES'!J12,CONCATENATE("TL",'CALCULS BRANCHES'!S13),'CALCULS BRANCHES'!K13)) | V10: =IF(COUNTIF('CALCULS BRANCHES'!B13,""),,ROUND('CALCULS BRANCHES'!AH13,0)&" ("&ROUND('CALCULS BRANCHES'!AK13,2)&")")
B11: ='CALCULS BRANCHES'!M5 -> 189 | D11: ='CALCULS BRANCHES'!F5 -> 10.6 | E11: =IF('CALCULS BRANCHES'!J5,CONCATENATE("FL",'CALCULS BRANCHES'!J5),'CALCULS BRANCHES'!I5) -> 1400 | G11: ='CALCULS BRANCHES'!AG5 -> 6.36 | K11: ='CALCULS BRANCHES'!B4 -> N12HE | M11: =IFERROR(VLOOKUP(N10,FREQUENCES!$A:$B,2,0),) | P11: ='CALCULS BRANCHES'!M14 | R11: ='CALCULS BRANCHES'!F14 | S11: =IF('CALCULS BRANCHES'!J14,CONCATENATE("FL",'CALCULS BRANCHES'!J14),'CALCULS BRANCHES'!I14) | U11: ='CALCULS BRANCHES'!AG14 | Y11: ='CALCULS BRANCHES'!B13 | AA11: =IFERROR(VLOOKUP(AB10,FREQUENCES!$A:$B,2,0),)
C12: ='CALCULS BRANCHES'!AF5 -> 193.68605 | D12: =IF(COUNTIF('CALCULS BRANCHES'!B5,""),"",TEXT(ROUND(CONVERT('CALCULS BRANCHES'!Y5,"kn",SpeedUnit),0),"000")) -> 099 | F12: =IF('CALCULS BRANCHES'!J5,IF('CALCULS BRANCHES'!I4,CONCATENATE("TA",'CALCULS BRANCHES'!Q5),CONCATENATE("TL",'CALCULS BRANCHES'!S5)),IF('CALCULS BRANCHES'!J4,CONCATENATE("TL",'CALCULS BRANCHES'!S5),'CALCULS BRANCHES'!K5)) -> 1500 | H12: =IF(COUNTIF('CALCULS BRANCHES'!B5,""),,ROUND('CALCULS BRANCHES'!AH5,0)&" ("&'CALCULS BRANCHES'!AK5&")") -> 6 (1,14) | N12: CHARTRES | Q12: ='CALCULS BRANCHES'!AF14 | R12: =IF(COUNTIF('CALCULS BRANCHES'!B14,""),"",TEXT(ROUND(CONVERT('CALCULS BRANCHES'!Y14,"kn",SpeedUnit),0),"000")) | T12: =IF('CALCULS BRANCHES'!J14,IF('CALCULS BRANCHES'!I13,CONCATENATE("TA",'CALCULS BRANCHES'!Q14),CONCATENATE("TL",'CALCULS BRANCHES'!S14)),IF('CALCULS BRANCHES'!J13,CONCATENATE("TL",'CALCULS BRANCHES'!S14),'CALCULS BRANCHES'!K14)) | V12: =IF(COUNTIF('CALCULS BRANCHES'!B14,""),,ROUND('CALCULS BRANCHES'!AH14,0)&" ("&ROUND('CALCULS BRANCHES'!AK14,2)&")")
B13: ='CALCULS BRANCHES'!M6 -> 206 | D13: ='CALCULS BRANCHES'!F6 -> 11.3 | E13: =IF('CALCULS BRANCHES'!J6,CONCATENATE("FL",'CALCULS BRANCHES'!J6),'CALCULS BRANCHES'!I6) -> 1900 | G13: ='CALCULS BRANCHES'!AG6 -> 6.78 | K13: ='CALCULS BRANCHES'!B5 -> EPR | M13: =IFERROR(VLOOKUP(N12,FREQUENCES!$A:$B,2,0),) -> 119.205 | P13: ='CALCULS BRANCHES'!M15 | R13: ='CALCULS BRANCHES'!F15 | S13: =IF('CALCULS BRANCHES'!J15,CONCATENATE("FL",'CALCULS BRANCHES'!J15),'CALCULS BRANCHES'!I15) | U13: ='CALCULS BRANCHES'!AG15 | Y13: ='CALCULS BRANCHES'!B14 | AA13: =IFERROR(VLOOKUP(AB12,FREQUENCES!$A:$B,2,0),)
C14: ='CALCULS BRANCHES'!AF6 -> 212.59824 | D14: =IF(COUNTIF('CALCULS BRANCHES'!B6,""),"",TEXT(ROUND(CONVERT('CALCULS BRANCHES'!Y6,"kn",SpeedUnit),0),"000")) -> 098 | F14: =IF('CALCULS BRANCHES'!J6,IF('CALCULS BRANCHES'!I5,CONCATENATE("TA",'CALCULS BRANCHES'!Q6),CONCATENATE("TL",'CALCULS BRANCHES'!S6)),IF('CALCULS BRANCHES'!J5,CONCATENATE("TL",'CALCULS BRANCHES'!S6),'CALCULS BRANCHES'!K6)) -> 1400 | H14: =IF(COUNTIF('CALCULS BRANCHES'!B6,""),,ROUND('CALCULS BRANCHES'!AH6,0)&" ("&ROUND('CALCULS BRANCHES'!AK6,2)&")") -> 6 (0,59) | Q14: ='CALCULS BRANCHES'!AF15 | R14: =IF(COUNTIF('CALCULS BRANCHES'!B15,""),"",TEXT(ROUND(CONVERT('CALCULS BRANCHES'!Y15,"kn",SpeedUnit),0),"000")) | T14: =IF('CALCULS BRANCHES'!J15,IF('CALCULS BRANCHES'!I14,CONCATENATE("TA",'CALCULS BRANCHES'!Q15),CONCATENATE("TL",'CALCULS BRANCHES'!S15)),IF('CALCULS BRANCHES'!J14,CONCATENATE("TL",'CALCULS BRANCHES'!S15),'CALCULS BRANCHES'!K15)) | V14: =IF(COUNTIF('CALCULS BRANCHES'!B15,""),,ROUND('CALCULS BRANCHES'!AH15,0)&" ("&ROUND('CALCULS BRANCHES'!AK15,2)&")")
B15: ='CALCULS BRANCHES'!M7 -> 335 | D15: ='CALCULS BRANCHES'!F7 -> 16.2 | E15: =IF('CALCULS BRANCHES'!J7,CONCATENATE("FL",'CALCULS BRANCHES'!J7),'CALCULS BRANCHES'!I7) -> 1900 | G15: ='CALCULS BRANCHES'!AG7 -> 9.72 | K15: ='CALCULS BRANCHES'!B6 -> LFOR | M15: =IFERROR(VLOOKUP(N14,FREQUENCES!$A:$B,2,0),) | P15: ='CALCULS BRANCHES'!M16 | R15: ='CALCULS BRANCHES'!F16 | S15: =IF('CALCULS BRANCHES'!J16,CONCATENATE("FL",'CALCULS BRANCHES'!J16),'CALCULS BRANCHES'!I16) | U15: ='CALCULS BRANCHES'!AG16 | Y15: ='CALCULS BRANCHES'!B15 | AA15: =IFERROR(VLOOKUP(AB14,FREQUENCES!$A:$B,2,0),)
C16: ='CALCULS BRANCHES'!AF7 -> 335.14999 | D16: =IF(COUNTIF('CALCULS BRANCHES'!B7,""),"",TEXT(ROUND(CONVERT('CALCULS BRANCHES'!Y7,"kn",SpeedUnit),0),"000")) -> 098 | F16: =IF('CALCULS BRANCHES'!J7,IF('CALCULS BRANCHES'!I6,CONCATENATE("TA",'CALCULS BRANCHES'!Q7),CONCATENATE("TL",'CALCULS BRANCHES'!S7)),IF('CALCULS BRANCHES'!J6,CONCATENATE("TL",'CALCULS BRANCHES'!S7),'CALCULS BRANCHES'!K7)) -> 1500 | H16: =IF(COUNTIF('CALCULS BRANCHES'!B7,""),,ROUND('CALCULS BRANCHES'!AH7,0)&" ("&ROUND('CALCULS BRANCHES'!AK7,2)&")") -> 11 (0,3) | Q16: ='CALCULS BRANCHES'!AF16 | R16: =IF(COUNTIF('CALCULS BRANCHES'!B16,""),"",TEXT(ROUND(CONVERT('CALCULS BRANCHES'!Y16,"kn",SpeedUnit),0),"000")) | T16: =IF('CALCULS BRANCHES'!J16,IF('CALCULS BRANCHES'!I15,CONCATENATE("TA",'CALCULS BRANCHES'!Q16),CONCATENATE("TL",'CALCULS BRANCHES'!S16)),IF('CALCULS BRANCHES'!J15,CONCATENATE("TL",'CALCULS BRANCHES'!S16),'CALCULS BRANCHES'!K16)) | V16: =IF(COUNTIF('CALCULS BRANCHES'!B16,""),,ROUND('CALCULS BRANCHES'!AH16,0)&" ("&ROUND('CALCULS BRANCHES'!AK16,2)&")")
B17: ='CALCULS BRANCHES'!M8 | D17: ='CALCULS BRANCHES'!F8 | E17: =IF('CALCULS BRANCHES'!J8,CONCATENATE("FL",'CALCULS BRANCHES'!J8),'CALCULS BRANCHES'!I8) | G17: ='CALCULS BRANCHES'!AG8 | K17: ='CALCULS BRANCHES'!B7 -> LFON | M17: =IFERROR(VLOOKUP(N16,FREQUENCES!$A:$B,2,0),) | P17: ='CALCULS BRANCHES'!M17 | R17: ='CALCULS BRANCHES'!F17 | S17: =IF('CALCULS BRANCHES'!J17,CONCATENATE("FL",'CALCULS BRANCHES'!J17),'CALCULS BRANCHES'!I17) | U17: ='CALCULS BRANCHES'!AG17 | Y17: ='CALCULS BRANCHES'!B16 | AA17: =IFERROR(VLOOKUP(AB16,FREQUENCES!$A:$B,2,0),)
C18: ='CALCULS BRANCHES'!AF8 | D18: =IF(COUNTIF('CALCULS BRANCHES'!B8,""),"",TEXT(ROUND(CONVERT('CALCULS BRANCHES'!Y8,"kn",SpeedUnit),0),"000")) | F18: =IF('CALCULS BRANCHES'!J8,IF('CALCULS BRANCHES'!I7,CONCATENATE("TA",'CALCULS BRANCHES'!Q8),CONCATENATE("TL",'CALCULS BRANCHES'!S8)),IF('CALCULS BRANCHES'!J7,CONCATENATE("TL",'CALCULS BRANCHES'!S8),'CALCULS BRANCHES'!K8)) | H18: =IF(COUNTIF('CALCULS BRANCHES'!B8,""),,ROUND('CALCULS BRANCHES'!AH8,0)&" ("&ROUND('CALCULS BRANCHES'!AK8,2)&")") | Q18: ='CALCULS BRANCHES'!AF17 | R18: =IF(COUNTIF('CALCULS BRANCHES'!B17,""),"",TEXT(ROUND(CONVERT('CALCULS BRANCHES'!Y17,"kn",SpeedUnit),0),"000")) | T18: =IF('CALCULS BRANCHES'!J17,IF('CALCULS BRANCHES'!I16,CONCATENATE("TA",'CALCULS BRANCHES'!Q17),CONCATENATE("TL",'CALCULS BRANCHES'!S17)),IF('CALCULS BRANCHES'!J16,CONCATENATE("TL",'CALCULS BRANCHES'!S17),'CALCULS BRANCHES'!K17)) | V18: =IF(COUNTIF('CALCULS BRANCHES'!B17,""),,ROUND('CALCULS BRANCHES'!AH17,0)&" ("&ROUND('CALCULS BRANCHES'!AK17,2)&")")
B19: ='CALCULS BRANCHES'!M9 | D19: ='CALCULS BRANCHES'!F9 | E19: =IF('CALCULS BRANCHES'!J9,CONCATENATE("FL",'CALCULS BRANCHES'!J9),'CALCULS BRANCHES'!I9) | G19: ='CALCULS BRANCHES'!AG9 | K19: ='CALCULS BRANCHES'!B8 | M19: =IFERROR(VLOOKUP(N18,FREQUENCES!$A:$B,2,0),) | P19: ='CALCULS BRANCHES'!M18 | R19: ='CALCULS BRANCHES'!F18 | S19: =IF('CALCULS BRANCHES'!J18,CONCATENATE("FL",'CALCULS BRANCHES'!J18),'CALCULS BRANCHES'!I18) | U19: ='CALCULS BRANCHES'!AG18 | Y19: ='CALCULS BRANCHES'!B17 | AA19: =IFERROR(VLOOKUP(AB18,FREQUENCES!$A:$B,2,0),)
C20: ='CALCULS BRANCHES'!AF9 | D20: =IF(COUNTIF('CALCULS BRANCHES'!B9,""),"",TEXT(ROUND(CONVERT('CALCULS BRANCHES'!Y9,"kn",SpeedUnit),0),"000")) | F20: =IF('CALCULS BRANCHES'!J9,IF('CALCULS BRANCHES'!I8,CONCATENATE("TA",'CALCULS BRANCHES'!Q9),CONCATENATE("TL",'CALCULS BRANCHES'!S9)),IF('CALCULS BRANCHES'!J8,CONCATENATE("TL",'CALCULS BRANCHES'!S9),'CALCULS BRANCHES'!K9)) | H20: =IF(COUNTIF('CALCULS BRANCHES'!B9,""),,ROUND('CALCULS BRANCHES'!AH9,0)&" ("&ROUND('CALCULS BRANCHES'!AK9,2)&")") | Q20: ='CALCULS BRANCHES'!AF18 | R20: =IF(COUNTIF('CALCULS BRANCHES'!B18,""),"",TEXT(ROUND(CONVERT('CALCULS BRANCHES'!Y18,"kn",SpeedUnit),0),"000")) | T20: =IF('CALCULS BRANCHES'!J18,IF('CALCULS BRANCHES'!I17,CONCATENATE("TA",'CALCULS BRANCHES'!Q18),CONCATENATE("TL",'CALCULS BRANCHES'!S18)),IF('CALCULS BRANCHES'!J17,CONCATENATE("TL",'CALCULS BRANCHES'!S18),'CALCULS BRANCHES'!K18)) | V20: =IF(COUNTIF('CALCULS BRANCHES'!B18,""),,ROUND('CALCULS BRANCHES'!AH18,0)&" ("&ROUND('CALCULS BRANCHES'!AK18,2)&")")
B21: ='CALCULS BRANCHES'!M10 | D21: ='CALCULS BRANCHES'!F10 | E21: =IF('CALCULS BRANCHES'!J10,CONCATENATE("FL",'CALCULS BRANCHES'!J10),'CALCULS BRANCHES'!I10) | G21: ='CALCULS BRANCHES'!AG10 | K21: ='CALCULS BRANCHES'!B9 | M21: =IFERROR(VLOOKUP(N20,FREQUENCES!$A:$B,2,0),) | P21: ='CALCULS BRANCHES'!M19 | R21: ='CALCULS BRANCHES'!F19 | S21: =IF('CALCULS BRANCHES'!J19,CONCATENATE("FL",'CALCULS BRANCHES'!J19),'CALCULS BRANCHES'!I19) | U21: ='CALCULS BRANCHES'!AG19 | Y21: ='CALCULS BRANCHES'!B18 | AA21: =IFERROR(VLOOKUP(AB20,FREQUENCES!$A:$B,2,0),)
C22: ='CALCULS BRANCHES'!AF10 | D22: =IF(COUNTIF('CALCULS BRANCHES'!B10,""),"",TEXT(ROUND(CONVERT('CALCULS BRANCHES'!Y10,"kn",SpeedUnit),0),"000")) | F22: =IF('CALCULS BRANCHES'!J10,IF('CALCULS BRANCHES'!I9,CONCATENATE("TA",'CALCULS BRANCHES'!Q10),CONCATENATE("TL",'CALCULS BRANCHES'!S10)),IF('CALCULS BRANCHES'!J9,CONCATENATE("TL",'CALCULS BRANCHES'!S10),'CALCULS BRANCHES'!K10)) | H22: =IF(COUNTIF('CALCULS BRANCHES'!B10,""),,ROUND('CALCULS BRANCHES'!AH10,0)&" ("&ROUND('CALCULS BRANCHES'!AK10,2)&")") | Q22: ='CALCULS BRANCHES'!AF19 | R22: =IF(COUNTIF('CALCULS BRANCHES'!B19,""),"",TEXT(ROUND(CONVERT('CALCULS BRANCHES'!Y19,"kn",SpeedUnit),0),"000")) | T22: =IF('CALCULS BRANCHES'!J19,IF('CALCULS BRANCHES'!I18,CONCATENATE("TA",'CALCULS BRANCHES'!Q19),CONCATENATE("TL",'CALCULS BRANCHES'!S19)),IF('CALCULS BRANCHES'!J18,CONCATENATE("TL",'CALCULS BRANCHES'!S19),'CALCULS BRANCHES'!K19)) | V22: =IF(COUNTIF('CALCULS BRANCHES'!B19,""),,ROUND('CALCULS BRANCHES'!AH19,0)&" ("&ROUND('CALCULS BRANCHES'!AK19,2)&")")
K23: ='CALCULS BRANCHES'!B10 | M23: =IFERROR(VLOOKUP(N22,FREQUENCES!$A:$B,2,0),) | Y23: ='CALCULS BRANCHES'!B19 | AA23: =IFERROR(VLOOKUP(AB22,FREQUENCES!$A:$B,2,0),)
D25: hh:mm | E25: L | I25: DEP (E/R) | L25: ARR | P25: QNH | Q25: 1023 | S25: Vw | T25: =WINTEM!J20 -> 15 | U25: kts | V25: Xm | W25: =T25*W26 -> 9 | X25: deg | Y25: AUTRES FREQUENCES
B26: PROC DEP | D26: =CARBURANT!A6/1440 -> 0.0069444444 | E26: =D26*FF_Procedures*24 -> 3 | G26: DATE | I26: 45109 | P26: OAT | Q26: 25 | R26: °C | S26: Dw | T26: =WINTEM!J21 -> 336 | U26: deg | V26: Fb | W26: =Fb -> 0.6 | Y26: LE BOURGET Approche | AB26: =IFERROR(VLOOKUP(Y26,FREQUENCES!$A:$B,2,0),) -> 118.8
B27: ETAPES | D27: =SUM('CALCULS BRANCHES'!AH2:AH19)/1440 -> 0.023034505 | E27: =SUM('CALCULS BRANCHES'!AJ:AJ) -> 7.3416321 | G27: HEURE | I27: 0.52361111 | L27: ='CALCULS BRANCHES'!D11 | P27: Z AD | Q27: 100 | R27: ft | S27: KVe | T27: =IF(T25>10,IF(T25>20,10,5),0) -> 5 | U27: kts | V27: Σ D | W27: =SUM('CALCULS BRANCHES'!F:F) -> 55.4 | X27: nm
B28: PROC ARR | D28: =CARBURANT!E6/1440 -> 0.0069444444 | E28: =D28*FF_Procedures*24 -> 3 | G28: HOBBS | I28: 123.4 | L28: =I28+SUM(D26:D28)*24 -> 124.28616 | N28: h,m | Y28: PONTOISE ATIS | AB28: =IFERROR(VLOOKUP(Y28,FREQUENCES!$A:$B,2,0),) -> 124.125
B29: RES. ROUTE | D29: =(CARBURANT!D6+CARBURANT!C13)/1440 -> 0.020833333 | E29: =D29*FF_Procedures*24 -> 9 | G29: CARBU (L) | I29: =FuelMax -> 117.5 | L29: =I29-SUM(E26:E28) -> 104.15837 | N29: L | P29: α | Q29: 0 | R29: 30 | S29: 45 | T29: 60 | U29: 90 | V29: deg
B30: RES. FINALE | D30: =CARBURANT!C12/1440 -> 0.020833333 | E30: =D30*FF_Procedures*24 -> 9 | G30: ROLL / 50 ft | J30: =Drd -> 334.15215 | K30: =Dd -> 603.31787 | L30: =Dra -> 211.33059 | M30: =Da -> 547.93019 | N30: m | P30: X | Q30: =$W25*SIN(RADIANS(Q29)) -> 0 | R30: =$W25*SIN(RADIANS(R29)) -> 4.5 | S30: =$W25*SIN(RADIANS(S29)) -> 6.363961 | T30: =$W25*SIN(RADIANS(T29)) -> 7.7942286 | U30: =$W25*SIN(RADIANS(U29)) -> 9 | V30: deg | Y30: GUARD | AB30: =IFERROR(VLOOKUP(Y30,FREQUENCES!$A:$B,2,0),) -> 121.5
B31: FUEL MIN 1 | D31: =CARBURANT!C16 -> 0.079829884 | E31: =SUM(E26:E30) -> 31.341632 | G31: AUTONOMIE | I31: =I29/M31/24 -> 0.2992828 | L31: FF | M31: =E31/(D31*24) -> 16.358552 | N31: L/h | P31: Tc | Q31: =U30 -> 9 | R31: =T30 -> 7.7942286 | S31: =S30 -> 6.363961 | T31: =R30 -> 4.5 | U31: =Q30 -> 0 | V31: s/min
B32: FUEL MIN 1+2 | D32: =IFERROR(__xludf.DUMMYFUNCTION("IMPORTRANGE(Etape2,""LOG!D31"")+D31"),0.15965976787858516) -> 0.15965977 | E32: =IFERROR(__xludf.DUMMYFUNCTION("IMPORTRANGE(Etape2,""LOG!E31"")+E31"),62.625132722493476) -> 62.625133 | G32: HEURE IVV | I32: =I27+I31-15/(24*60) -> 0.81247724

Sheet CALCULS BRANCHES
A1: From | B1: To | C1: HE (hh:mm) | D1: HR (hh:mm) | E1: Compteur (h.d) | F1: Dist (NM) | G1: Rv (°) | H1: Dm (°) | I1: Zi | J1: FL | K1: MSA | L1: Zsfc | M1: Rm (°) | N1: Zp | O1: Zd | P1: Zv | Q1: TA | R1: 1FL | S1: TL | T1: QNH | U1: OAT Ref | V1: OAT Ref Elev | W1: Vw (KTS) | X1: Dw (°) | Y1: Vi | Z1: Vc | AA1: Fb | AB1: Vp (KTS) | AC1: Vs (KTS) | AD1: X (°) | AE1: FF (L/H) | AF1: Cm (°) | AG1: T (MIN) | AH1: Tw (MIN) | AI1: F (L) | AJ1: Fw (L) | AK1: ReqFuel (MIN) | AL1: BurnedFuel (L)
A2: LFXU | B2: PTSW | C2: =IF(COUNTIF(B2,""),,LOG!I27+LOG!D26+AH2/1440) -> 0.53312458 | D2: =IF(COUNTIF(B2,""),,C2) -> 0.53312458 | E2: =IF(COUNTIF(B2,""),,LOG!I28+(D2-LOG!I27)*24) -> 123.62832 | F2: =IF(COUNTIF(B2,""),,ROUND(CONVERT(Distance(VLOOKUP(A2,WAYPOINTS!A:C,2,FALSE()),VLOOKUP(A2,WAYPOINTS!A:C,3,FALSE()),VLOOKUP(B2,WAYPOINTS!A:C,2,FALSE()),VLOOKUP(B2,WAYPOINTS!A:C,3,FALSE())),"m","Nmi"),1)) -> 6 | G2: =IF(COUNTIF(B2,""),,MOD(Bearing(VLOOKUP(A2,WAYPOINTS!A:C,2,FALSE()),VLOOKUP(A2,WAYPOINTS!A:C,3,FALSE()),VLOOKUP(B2,WAYPOINTS!A:C,2,FALSE()),VLOOKUP(B2,WAYPOINTS!A:C,3,FALSE())),360)) -> 253.68469 | H2: =IFERROR(__xludf.DUMMYFUNCTION("IF(COUNTIF(B2,""""),,ROUND(SUBSTITUTE(IMPORTXML(""https://www.ngdc.noaa.gov/geomag-web/calculators/calculateDeclination?lat1=""&SUBSTITUTE(VLOOKUP(A2,WAYPOINTS!A:C,2,FALSE()),"","",""."")&""&lon1=""&SUBSTITUTE(VLOOKUP(A2,WAYPOINTS!A:C,3,FALSE()),"","",""."&""")&""&key=zNEw7&resultFormat=xml"",""//declination""),""."","",""),2))"),1.85) -> 1.85 | I2: 1400 | K2: =IF(COUNTIF(B2,""),,ROUND(L2+1000,-2)) -> 1100 | L2: =IF(COUNTIF(B2,""),,ROUND(CONVERT(getElevation(AVERAGE(VLOOKUP(A2,WAYPOINTS!A:C,2,FALSE()),VLOOKUP(B2,WAYPOINTS!A:C,2,FALSE())),AVERAGE(VLOOKUP(A2,WAYPOINTS!A:C,3,FALSE()),VLOOKUP(B2,WAYPOINTS!A:C,3,FALSE()))),"m","ft"),0)) -> 74 | M2: =IF(COUNTIF(B2,""),,ROUND(G2-H2,0)) -> 252 | N2: =IF(COUNTIF(B2,""),,IF(J2,J2*100,PressureAltitude(I2,T2))) -> 1127 | O2: =IF(COUNTIF(B2,""),,IF(J2,DensityAltitude(J2*100,IsaDeviation(V2,U2)),DensityAltitude(PressureAltitude(I2,T2),IsaDeviation(PressureAltitude(V2,T2),U2)))) -> 2273.8952 | P2: =IF(COUNTIF(B2,""),,IF(J2,TrueAltitude(IndicatedAltitude(J2*100,T2),IsaDeviation(V2,U2)),TrueAltitude(I2,IsaDeviation(V2,U2)))) -> 1342.88 | Q2: =IF(COUNTIF(B2,""),,3000+L2) -> 3074 | R2: =IF(COUNTIF(B2,""),,MinimalFlightLevel(Q2,T2,M2)) -> 45 | S2: =IF(COUNTIF(B2,""),,TransitionLevel(Q2,T2)) -> 30 | T2: =IF(COUNTIF(B2,""),,LOG!Q$25) -> 1023 | U2: =IF(COUNTIF(B2,""),,LOG!Q$26) -> 25 | V2: =IF(COUNTIF(B2,""),,LOG!Q$27) -> 100 | W2: =IF(COUNTIF(B2,""),,SWITCH(WindMode,"Detailed",WINTEM!F2,"Average",AverageWindSpeed,"Manual",ManualWindSpeed)) -> 15 | X2: =IF(COUNTIF(B2,""),,SWITCH(WindMode,"Detailed",WINTEM!G2,"Average",AverageWindDirection,"Manual",ManualWindDirection)) -> 336 | Y2: =IF(COUNTIF(B2,""),,Z2+0) -> 98.580692 | Z2: =IF(COUNTIF(B2,""),,IF(J2,CorrectedAirSpeed(IndicatedAltitude(J2,T2),AB2,IsaDeviation(PressureAltitude(V2,T2),U2)),CorrectedAirSpeed(I2,AB2,IsaDeviation(PressureAltitude(V2,T2),U2)))) -> 98.580692 | AA2: =IF(COUNTIF(B2,""),,LOG!W$26) -> 0.6 | AB2: =IF(COUNTIF(B2,""),,60/AA2) -> 100 | AC2: =IF(COUNTIF(B2,""),,AB2*COS(RADIANS(AD2))-(W2*COS(RADIANS(M2-X2)))) -> 97.313105 | AD2: =IF(COUNTIF(B2,""),,DEGREES(ASIN(W2/AB2*SIN(RADIANS(M2-X2))))) -> -8.5793099 | AE2: =IF(COUNTIF(B2,""),,PERFORMANCE!H53) -> 13.280135 | AF2: =IF(COUNTIF(B2,""),,MOD(M2-AD2,360)) -> 260.57931 | AG2: =IF(COUNTIF(B2,""),,F2*60/AB2) -> 3.6 | AH2: =IF(COUNTIF(B2,""),,F2*60/AC2) -> 3.699399 | AI2: =IF(COUNTIF(B2,""),,AE2/60*AG2) -> 0.79680811 | AJ2: =IF(COUNTIF(B2,""),,AE2/60*AH2) -> 0.81880864 | AK2: =IF(COUNTIF(B2,""),,ROUND(ReqFuel(CARBURANT!G$20,CARBURANT!G$21,CARBURANT!G$22,CARBURANT!G$23,SUM(AH$2:AH2)),2)) -> 1.44 | AL2: =LOG!E26+AJ2 -> 3.8188086
A3: =IF(COUNTIF(B3,""),,B2) -> PTSW | B3: MEZER | C3: =IF(COUNTIF(B3,""),,IF(COUNTIF(B4,""),C2+AH3/1440+LOG!D$28,C2+AH3/1440)) -> 0.53434995 | D3: =IF(COUNTIF(B3,""),,C3) -> 0.53434995 | E3: =IF(COUNTIF(B3,""),,E2+(D3-D2)*24) -> 123.65773 | F3: =IF(COUNTIF(B3,""),,ROUND(CONVERT(Distance(VLOOKUP(A3,WAYPOINTS!A:C,2,FALSE()),VLOOKUP(A3,WAYPOINTS!A:C,3,FALSE()),VLOOKUP(B3,WAYPOINTS!A:C,2,FALSE()),VLOOKUP(B3,WAYPOINTS!A:C,3,FALSE())),"m","Nmi"),1)) -> 3.1 | G3: =IF(COUNTIF(B3,""),,MOD(Bearing(VLOOKUP(A3,WAYPOINTS!A:C,2,FALSE()),VLOOKUP(A3,WAYPOINTS!A:C,3,FALSE()),VLOOKUP(B3,WAYPOINTS!A:C,2,FALSE()),VLOOKUP(B3,WAYPOINTS!A:C,3,FALSE())),360)) -> 223.12897 | H3: =IFERROR(__xludf.DUMMYFUNCTION("IF(COUNTIF(B3,""""),,ROUND(SUBSTITUTE(IMPORTXML(""https://www.ngdc.noaa.gov/geomag-web/calculators/calculateDeclination?lat1=""&SUBSTITUTE(VLOOKUP(A3,WAYPOINTS!A:C,2,FALSE()),"","",""."")&""&lon1=""&SUBSTITUTE(VLOOKUP(A3,WAYPOINTS!A:C,3,FALSE()),"","",""."&""")&""&key=zNEw7&resultFormat=xml"",""//declination""),""."","",""),2))"),1.81) -> 1.81 | I3: 1400 | K3: =IF(COUNTIF(B3,""),,ROUND(L3+1000,-2)) -> 1500 | L3: =IF(COUNTIF(B3,""),,ROUND(CONVERT(getElevation(AVERAGE(VLOOKUP(A3,WAYPOINTS!A:C,2,FALSE()),VLOOKUP(B3,WAYPOINTS!A:C,2,FALSE())),AVERAGE(VLOOKUP(A3,WAYPOINTS!A:C,3,FALSE()),VLOOKUP(B3,WAYPOINTS!A:C,3,FALSE()))),"m","ft"),0)) -> 494 | M3: =IF(COUNTIF(B3,""),,ROUND(G3-H3,0)) -> 221 | N3: =IF(COUNTIF(B3,""),,IF(J3,J3*100,PressureAltitude(I3,T3))) -> 1127 | O3: =IF(COUNTIF(B3,""),,IF(J3,DensityAltitude(J3*100,IsaDeviation(V3,U3)),DensityAltitude(PressureAltitude(I3,T3),IsaDeviation(PressureAltitude(V3,T3),U3)))) -> 2273.8952 | P3: =IF(COUNTIF(B3,""),,IF(J3,TrueAltitude(IndicatedAltitude(J3*100,T3),IsaDeviation(V3,U3)),TrueAltitude(I3,IsaDeviation(V3,U3)))) -> 1342.88 | Q3: =IF(COUNTIF(B3,""),,3000+L3) -> 3494 | R3: =IF(COUNTIF(B3,""),,MinimalFlightLevel(Q3,T3,M3)) -> 45 | S3: =IF(COUNTIF(B3,""),,TransitionLevel(Q3,T3)) -> 35 | T3: =IF(COUNTIF(B3,""),,LOG!Q$25) -> 1023 | U3: =IF(COUNTIF(B3,""),,LOG!Q$26) -> 25 | V3: =IF(COUNTIF(B3,""),,LOG!Q$27) -> 100 | W3: =IF(COUNTIF(B3,""),,SWITCH(WindMode,"Detailed",WINTEM!F3,"Average",AverageWindSpeed,"Manual",ManualWindSpeed)) -> 15 | X3: =IF(COUNTIF(B3,""),,SWITCH(WindMode,"Detailed",WINTEM!G3,"Average",AverageWindDirection,"Manual",ManualWindDirection)) -> 336 | Y3: =IF(COUNTIF(B3,""),,Z3+0) -> 98.580692 | Z3: =IF(COUNTIF(B3,""),,IF(J3,CorrectedAirSpeed(IndicatedAltitude(J3,T3),AB3,IsaDeviation(PressureAltitude(V3,T3),U3)),CorrectedAirSpeed(I3,AB3,IsaDeviation(PressureAltitude(V3,T3),U3)))) -> 98.580692 | AA3: =IF(COUNTIF(B3,""),,LOG!W$26) -> 0.6 | AB3: =IF(COUNTIF(B3,""),,60/AA3) -> 100 | AC3: =IF(COUNTIF(B3,""),,AB3*COS(RADIANS(AD3))-(W3*COS(RADIANS(M3-X3)))) -> 105.4109 | AD3: =IF(COUNTIF(B3,""),,DEGREES(ASIN(W3/AB3*SIN(RADIANS(M3-X3))))) -> -7.8133358 | AE3: =IF(COUNTIF(B3,""),,PERFORMANCE!H54) -> 13.280135 | AF3: =IF(COUNTIF(B3,""),,MOD(M3-AD3,360)) -> 228.81334 | AG3: =IF(COUNTIF(B3,""),,F3*60/AB3) -> 1.86 | AH3: =IF(COUNTIF(B3,""),,F3*60/AC3) -> 1.7645235 | AI3: =IF(COUNTIF(B3,""),,AE3/60*AG3) -> 0.41168419 | AJ3: =IF(COUNTIF(B3,""),,AE3/60*AH3) -> 0.39055183 | AK3: =IF(COUNTIF(B3,""),,ROUND(ReqFuel(CARBURANT!G$20,CARBURANT!G$21,CARBURANT!G$22,CARBURANT!G$23,SUM(AH$2:AH3)),2)) -> 1.39 | AL3: =IF(COUNTIF(B3,""),,IF(COUNTIF(B4,""),AL2+AJ3+LOG!E$28,AL2+AJ3)) -> 4.2093605
A4: =IF(COUNTIF(B4,""),,B3) -> MEZER | B4: N12HE | C4: =IF(COUNTIF(B4,""),,IF(COUNTIF(B5,""),C3+AH4/1440+LOG!D$28,C3+AH4/1440)) -> 0.53739386 | D4: =IF(COUNTIF(B4,""),,C4) -> 0.53739386 | E4: =IF(COUNTIF(B4,""),,E3+(D4-D3)*24) -> 123.73079 | F4: =IF(COUNTIF(B4,""),,ROUND(CONVERT(Distance(VLOOKUP(A4,WAYPOINTS!A:C,2,FALSE()),VLOOKUP(A4,WAYPOINTS!A:C,3,FALSE()),VLOOKUP(B4,WAYPOINTS!A:C,2,FALSE()),VLOOKUP(B4,WAYPOINTS!A:C,3,FALSE())),"m","Nmi"),1)) -> 8.2 | G4: =IF(COUNTIF(B4,""),,MOD(Bearing(VLOOKUP(A4,WAYPOINTS!A:C,2,FALSE()),VLOOKUP(A4,WAYPOINTS!A:C,3,FALSE()),VLOOKUP(B4,WAYPOINTS!A:C,2,FALSE()),VLOOKUP(B4,WAYPOINTS!A:C,3,FALSE())),360)) -> 190.50882 | H4: =IFERROR(__xludf.DUMMYFUNCTION("IF(COUNTIF(B4,""""),,ROUND(SUBSTITUTE(IMPORTXML(""https://www.ngdc.noaa.gov/geomag-web/calculators/calculateDeclination?lat1=""&SUBSTITUTE(VLOOKUP(A4,WAYPOINTS!A:C,2,FALSE()),"","",""."")&""&lon1=""&SUBSTITUTE(VLOOKUP(A4,WAYPOINTS!A:C,3,FALSE()),"","",""."&""")&""&key=zNEw7&resultFormat=xml"",""//declination""),""."","",""),2))"),1.8) -> 1.8 | I4: 1400 | K4: =IF(COUNTIF(B4,""),,ROUND(L4+1000,-2)) -> 1400 | L4: =IF(COUNTIF(B4,""),,ROUND(CONVERT(getElevation(AVERAGE(VLOOKUP(A4,WAYPOINTS!A:C,2,FALSE()),VLOOKUP(B4,WAYPOINTS!A:C,2,FALSE())),AVERAGE(VLOOKUP(A4,WAYPOINTS!A:C,3,FALSE()),VLOOKUP(B4,WAYPOINTS!A:C,3,FALSE()))),"m","ft"),0)) -> 406 | M4: =IF(COUNTIF(B4,""),,ROUND(G4-H4,0)) -> 189 | N4: =IF(COUNTIF(B4,""),,IF(J4,J4*100,PressureAltitude(I4,T4))) -> 1127 | O4: =IF(COUNTIF(B4,""),,IF(J4,DensityAltitude(J4*100,IsaDeviation(V4,U4)),DensityAltitude(PressureAltitude(I4,T4),IsaDeviation(PressureAltitude(V4,T4),U4)))) -> 2273.8952 | P4: =IF(COUNTIF(B4,""),,IF(J4,TrueAltitude(IndicatedAltitude(J4*100,T4),IsaDeviation(V4,U4)),TrueAltitude(I4,IsaDeviation(V4,U4)))) -> 1342.88 | Q4: =IF(COUNTIF(B4,""),,3000+L4) -> 3406 | R4: =IF(COUNTIF(B4,""),,MinimalFlightLevel(Q4,T4,M4)) -> 45 | S4: =IF(COUNTIF(B4,""),,TransitionLevel(Q4,T4)) -> 35 | T4: =IF(COUNTIF(B4,""),,LOG!Q$25) -> 1023 | U4: =IF(COUNTIF(B4,""),,LOG!Q$26) -> 25 | V4: =IF(COUNTIF(B4,""),,LOG!Q$27) -> 100 | W4: =IF(COUNTIF(B4,""),,SWITCH(WindMode,"Detailed",WINTEM!F4,"Average",AverageWindSpeed,"Manual",ManualWindSpeed)) -> 15 | X4: =IF(COUNTIF(B4,""),,SWITCH(WindMode,"Detailed",WINTEM!G4,"Average",AverageWindDirection,"Manual",ManualWindDirection)) -> 336 | Y4: =IF(COUNTIF(B4,""),,Z4+0) -> 98.580692 | Z4: =IF(COUNTIF(B4,""),,IF(J4,CorrectedAirSpeed(IndicatedAltitude(J4,T4),AB4,IsaDeviation(PressureAltitude(V4,T4),U4)),CorrectedAirSpeed(I4,AB4,IsaDeviation(PressureAltitude(V4,T4),U4)))) -> 98.580692 | AA4: =IF(COUNTIF(B4,""),,LOG!W$26) -> 0.6 | AB4: =IF(COUNTIF(B4,""),,60/AA4) -> 100 | AC4: =IF(COUNTIF(B4,""),,AB4*COS(RADIANS(AD4))-(W4*COS(RADIANS(M4-X4)))) -> 112.24579 | AD4: =IF(COUNTIF(B4,""),,DEGREES(ASIN(W4/AB4*SIN(RADIANS(M4-X4))))) -> -4.6860502 | AE4: =IF(COUNTIF(B4,""),,PERFORMANCE!H55) -> 13.280135 | AF4: =IF(COUNTIF(B4,""),,MOD(M4-AD4,360)) -> 193.68605 | AG4: =IF(COUNTIF(B4,""),,F4*60/AB4) -> 4.92 | AH4: =IF(COUNTIF(B4,""),,F4*60/AC4) -> 4.3832379 | AI4: =IF(COUNTIF(B4,""),,AE4/60*AG4) -> 1.0889711 | AJ4: =IF(COUNTIF(B4,""),,AE4/60*AH4) -> 0.97016653 | AK4: =IF(COUNTIF(B4,""),,ROUND(ReqFuel(CARBURANT!G$20,CARBURANT!G$21,CARBURANT!G$22,CARBURANT!G$23,SUM(AH$2:AH4)),2)) -> 1.28 | AL4: =IF(COUNTIF(B4,""),,IF(COUNTIF(B5,""),AL3+AJ4+LOG!E$28,AL3+AJ4)) -> 5.179527
A5: =IF(COUNTIF(B5,""),,B4) -> N12HE | B5: EPR | C5: =IF(COUNTIF(B5,""),,IF(COUNTIF(B6,""),C4+AH5/1440+LOG!D$28,C4+AH5/1440)) -> 0.54132868 | D5: =IF(COUNTIF(B5,""),,C5) -> 0.54132868 | E5: =IF(COUNTIF(B5,""),,E4+(D5-D4)*24) -> 123.82522 | F5: =IF(COUNTIF(B5,""),,ROUND(CONVERT(Distance(VLOOKUP(A5,WAYPOINTS!A:C,2,FALSE()),VLOOKUP(A5,WAYPOINTS!A:C,3,FALSE()),VLOOKUP(B5,WAYPOINTS!A:C,2,FALSE()),VLOOKUP(B5,WAYPOINTS!A:C,3,FALSE())),"m","Nmi"),1)) -> 10.6 | G5: =IF(COUNTIF(B5,""),,MOD(Bearing(VLOOKUP(A5,WAYPOINTS!A:C,2,FALSE()),VLOOKUP(A5,WAYPOINTS!A:C,3,FALSE()),VLOOKUP(B5,WAYPOINTS!A:C,2,FALSE()),VLOOKUP(B5,WAYPOINTS!A:C,3,FALSE())),360)) -> 190.51401 | H5: =IFERROR(__xludf.DUMMYFUNCTION("IF(COUNTIF(B5,""""),,ROUND(SUBSTITUTE(IMPORTXML(""https://www.ngdc.noaa.gov/geomag-web/calculators/calculateDeclination?lat1=""&SUBSTITUTE(VLOOKUP(A5,WAYPOINTS!A:C,2,FALSE()),"","",""."")&""&lon1=""&SUBSTITUTE(VLOOKUP(A5,WAYPOINTS!A:C,3,FALSE()),"","",""."&""")&""&key=zNEw7&resultFormat=xml"",""//declination""),""."","",""),2))"),1.79) -> 1.79 | I5: 1400 | K5: =IF(COUNTIF(B5,""),,ROUND(L5+1000,-2)) -> 1500 | L5: =IF(COUNTIF(B5,""),,ROUND(CONVERT(getElevation(AVERAGE(VLOOKUP(A5,WAYPOINTS!A:C,2,FALSE()),VLOOKUP(B5,WAYPOINTS!A:C,2,FALSE())),AVERAGE(VLOOKUP(A5,WAYPOINTS!A:C,3,FALSE()),VLOOKUP(B5,WAYPOINTS!A:C,3,FALSE()))),"m","ft"),0)) -> 515 | M5: =IF(COUNTIF(B5,""),,ROUND(G5-H5,0)) -> 189 | N5: =IF(COUNTIF(B5,""),,IF(J5,J5*100,PressureAltitude(I5,T5))) -> 1127 | O5: =IF(COUNTIF(B5,""),,IF(J5,DensityAltitude(J5*100,IsaDeviation(V5,U5)),DensityAltitude(PressureAltitude(I5,T5),IsaDeviation(PressureAltitude(V5,T5),U5)))) -> 2273.8952 | P5: =IF(COUNTIF(B5,""),,IF(J5,TrueAltitude(IndicatedAltitude(J5*100,T5),IsaDeviation(V5,U5)),TrueAltitude(I5,IsaDeviation(V5,U5)))) -> 1342.88 | Q5: =IF(COUNTIF(B5,""),,3000+L5) -> 3515 | R5: =IF(COUNTIF(B5,""),,MinimalFlightLevel(Q5,T5,M5)) -> 45 | S5: =IF(COUNTIF(B5,""),,TransitionLevel(Q5,T5)) -> 35 | T5: =IF(COUNTIF(B5,""),,LOG!Q$25) -> 1023 | U5: =IF(COUNTIF(B5,""),,LOG!Q$26) -> 25 | V5: =IF(COUNTIF(B5,""),,LOG!Q$27) -> 100 | W5: =IF(COUNTIF(B5,""),,SWITCH(WindMode,"Detailed",WINTEM!F5,"Average",AverageWindSpeed,"Manual",ManualWindSpeed)) -> 15 | X5: =IF(COUNTIF(B5,""),,SWITCH(WindMode,"Detailed",WINTEM!G5,"Average",AverageWindDirection,"Manual",ManualWindDirection)) -> 336 | Y5: =IF(COUNTIF(B5,""),,Z5+0) -> 98.580692 | Z5: =IF(COUNTIF(B5,""),,IF(J5,CorrectedAirSpeed(IndicatedAltitude(J5,T5),AB5,IsaDeviation(PressureAltitude(V5,T5),U5)),CorrectedAirSpeed(I5,AB5,IsaDeviation(PressureAltitude(V5,T5),U5)))) -> 98.580692 | AA5: =IF(COUNTIF(B5,""),,LOG!W$26) -> 0.6 | AB5: =IF(COUNTIF(B5,""),,60/AA5) -> 100 | AC5: =IF(COUNTIF(B5,""),,AB5*COS(RADIANS(AD5))-(W5*COS(RADIANS(M5-X5)))) -> 112.24579 | AD5: =IF(COUNTIF(B5,""),,DEGREES(ASIN(W5/AB5*SIN(RADIANS(M5-X5))))) -> -4.6860502 | AE5: =IF(COUNTIF(B5,""),,PERFORMANCE!H56) -> 13.280135 | AF5: =IF(COUNTIF(B5,""),,MOD(M5-AD5,360)) -> 193.68605 | AG5: =IF(COUNTIF(B5,""),,F5*60/AB5) -> 6.36 | AH5: =IF(COUNTIF(B5,""),,F5*60/AC5) -> 5.6661368 | AI5: =IF(COUNTIF(B5,""),,AE5/60*AG5) -> 1.4076943 | AJ5: =IF(COUNTIF(B5,""),,AE5/60*AH5) -> 1.2541177 | AK5: =IF(COUNTIF(B5,""),,ROUND(ReqFuel(CARBURANT!G$20,CARBURANT!G$21,CARBURANT!G$22,CARBURANT!G$23,SUM(AH$2:AH5)),2)) -> 1.14 | AL5: =IF(COUNTIF(B5,""),,IF(COUNTIF(B6,""),AL4+AJ5+LOG!E$28,AL4+AJ5)) -> 6.4336447
A6: =IF(COUNTIF(B6,""),,B5) -> EPR | B6: LFOR | C6: =IF(COUNTIF(B6,""),,IF(COUNTIF(B7,""),C5+AH6/1440+LOG!D$28,C5+AH6/1440)) -> 0.54564907 | D6: =IF(COUNTIF(B6,""),,C6) -> 0.54564907 | E6: =IF(COUNTIF(B6,""),,E5+(D6-D5)*24) -> 123.92891 | F6: =IF(COUNTIF(B6,""),,ROUND(CONVERT(Distance(VLOOKUP(A6,WAYPOINTS!A:C,2,FALSE()),VLOOKUP(A6,WAYPOINTS!A:C,3,FALSE()),VLOOKUP(B6,WAYPOINTS!A:C,2,FALSE()),VLOOKUP(B6,WAYPOINTS!A:C,3,FALSE())),"m","Nmi"),1)) -> 11.3 | G6: =IF(COUNTIF(B6,""),,MOD(Bearing(VLOOKUP(A6,WAYPOINTS!A:C,2,FALSE()),VLOOKUP(A6,WAYPOINTS!A:C,3,FALSE()),VLOOKUP(B6,WAYPOINTS!A:C,2,FALSE()),VLOOKUP(B6,WAYPOINTS!A:C,3,FALSE())),360)) -> 207.82269 | H6: =IFERROR(__xludf.DUMMYFUNCTION("IF(COUNTIF(B6,""""),,ROUND(SUBSTITUTE(IMPORTXML(""https://www.ngdc.noaa.gov/geomag-web/calculators/calculateDeclination?lat1=""&SUBSTITUTE(VLOOKUP(A6,WAYPOINTS!A:C,2,FALSE()),"","",""."")&""&lon1=""&SUBSTITUTE(VLOOKUP(A6,WAYPOINTS!A:C,3,FALSE()),"","",""."&""")&""&key=zNEw7&resultFormat=xml"",""//declination""),""."","",""),2))"),1.79) -> 1.79 | I6: 1900 | K6: =IF(COUNTIF(B6,""),,ROUND(L6+1000,-2)) -> 1400 | L6: =IF(COUNTIF(B6,""),,ROUND(CONVERT(getElevation(AVERAGE(VLOOKUP(A6,WAYPOINTS!A:C,2,FALSE()),VLOOKUP(B6,WAYPOINTS!A:C,2,FALSE())),AVERAGE(VLOOKUP(A6,WAYPOINTS!A:C,3,FALSE()),VLOOKUP(B6,WAYPOINTS!A:C,3,FALSE()))),"m","ft"),0)) -> 382 | M6: =IF(COUNTIF(B6,""),,ROUND(G6-H6,0)) -> 206 | N6: =IF(COUNTIF(B6,""),,IF(J6,J6*100,PressureAltitude(I6,T6))) -> 1627 | O6: =IF(COUNTIF(B6,""),,IF(J6,DensityAltitude(J6*100,IsaDeviation(V6,U6)),DensityAltitude(PressureAltitude(I6,T6),IsaDeviation(PressureAltitude(V6,T6),U6)))) -> 2773.8952 | P6: =IF(COUNTIF(B6,""),,IF(J6,TrueAltitude(IndicatedAltitude(J6*100,T6),IsaDeviation(V6,U6)),TrueAltitude(I6,IsaDeviation(V6,U6)))) -> 1822.48 | Q6: =IF(COUNTIF(B6,""),,3000+L6) -> 3382 | R6: =IF(COUNTIF(B6,""),,MinimalFlightLevel(Q6,T6,M6)) -> 45 | S6: =IF(COUNTIF(B6,""),,TransitionLevel(Q6,T6)) -> 35 | T6: =IF(COUNTIF(B6,""),,LOG!Q$25) -> 1023 | U6: =IF(COUNTIF(B6,""),,LOG!Q$26) -> 25 | V6: =IF(COUNTIF(B6,""),,LOG!Q$27) -> 100 | W6: =IF(COUNTIF(B6,""),,SWITCH(WindMode,"Detailed",WINTEM!F6,"Average",AverageWindSpeed,"Manual",ManualWindSpeed)) -> 15 | X6: =IF(COUNTIF(B6,""),,SWITCH(WindMode,"Detailed",WINTEM!G6,"Average",AverageWindDirection,"Manual",ManualWindDirection)) -> 336 | Y6: =IF(COUNTIF(B6,""),,Z6+0) -> 98.080692 | Z6: =IF(COUNTIF(B6,""),,IF(J6,CorrectedAirSpeed(IndicatedAltitude(J6,T6),AB6,IsaDeviation(PressureAltitude(V6,T6),U6)),CorrectedAirSpeed(I6,AB6,IsaDeviation(PressureAltitude(V6,T6),U6)))) -> 98.080692 | AA6: =IF(COUNTIF(B6,""),,LOG!W$26) -> 0.6 | AB6: =IF(COUNTIF(B6,""),,60/AA6) -> 100 | AC6: =IF(COUNTIF(B6,""),,AB6*COS(RADIANS(AD6))-(W6*COS(RADIANS(M6-X6)))) -> 108.97944 | AD6: =IF(COUNTIF(B6,""),,DEGREES(ASIN(W6/AB6*SIN(RADIANS(M6-X6))))) -> -6.5982417 | AE6: =IF(COUNTIF(B6,""),,PERFORMANCE!H57) -> 13.280135 | AF6: =IF(COUNTIF(B6,""),,MOD(M6-AD6,360)) -> 212.59824 | AG6: =IF(COUNTIF(B6,""),,F6*60/AB6) -> 6.78 | AH6: =IF(COUNTIF(B6,""),,F6*60/AC6) -> 6.2213568 | AI6: =IF(COUNTIF(B6,""),,AE6/60*AG6) -> 1.5006553 | AJ6: =IF(COUNTIF(B6,""),,AE6/60*AH6) -> 1.3770076 | AK6: =IF(COUNTIF(B6,""),,ROUND(ReqFuel(CARBURANT!G$20,CARBURANT!G$21,CARBURANT!G$22,CARBURANT!G$23,SUM(AH$2:AH6)),2)) -> 0.59 | AL6: =IF(COUNTIF(B6,""),,IF(COUNTIF(B7,""),AL5+AJ6+LOG!E$28,AL5+AJ6)) -> 7.8106524
A7: =IF(COUNTIF(B7,""),,B6) -> LFOR | B7: LFON | C7: =IF(COUNTIF(B7,""),,IF(COUNTIF(B8,""),C6+AH7/1440+LOG!D$28,C6+AH7/1440)) -> 0.5605345 | D7: =IF(COUNTIF(B7,""),,C7) -> 0.5605345 | E7: =IF(COUNTIF(B7,""),,E6+(D7-D6)*24) -> 124.28616 | F7: =IF(COUNTIF(B7,""),,ROUND(CONVERT(Distance(VLOOKUP(A7,WAYPOINTS!A:C,2,FALSE()),VLOOKUP(A7,WAYPOINTS!A:C,3,FALSE()),VLOOKUP(B7,WAYPOINTS!A:C,2,FALSE()),VLOOKUP(B7,WAYPOINTS!A:C,3,FALSE())),"m","Nmi"),1)) -> 16.2 | G7: =IF(COUNTIF(B7,""),,MOD(Bearing(VLOOKUP(A7,WAYPOINTS!A:C,2,FALSE()),VLOOKUP(A7,WAYPOINTS!A:C,3,FALSE()),VLOOKUP(B7,WAYPOINTS!A:C,2,FALSE()),VLOOKUP(B7,WAYPOINTS!A:C,3,FALSE())),360)) -> 336.5359 | H7: =IFERROR(__xludf.DUMMYFUNCTION("IF(COUNTIF(B7,""""),,ROUND(SUBSTITUTE(IMPORTXML(""https://www.ngdc.noaa.gov/geomag-web/calculators/calculateDeclination?lat1=""&SUBSTITUTE(VLOOKUP(A7,WAYPOINTS!A:C,2,FALSE()),"","",""."")&""&lon1=""&SUBSTITUTE(VLOOKUP(A7,WAYPOINTS!A:C,3,FALSE()),"","",""."&""")&""&key=zNEw7&resultFormat=xml"",""//declination""),""."","",""),2))"),1.76) -> 1.76 | I7: 1900 | K7: =IF(COUNTIF(B7,""),,ROUND(L7+1000,-2)) -> 1500 | L7: =IF(COUNTIF(B7,""),,ROUND(CONVERT(getElevation(AVERAGE(VLOOKUP(A7,WAYPOINTS!A:C,2,FALSE()),VLOOKUP(B7,WAYPOINTS!A:C,2,FALSE())),AVERAGE(VLOOKUP(A7,WAYPOINTS!A:C,3,FALSE()),VLOOKUP(B7,WAYPOINTS!A:C,3,FALSE()))),"m","ft"),0)) -> 536 | M7: =IF(COUNTIF(B7,""),,ROUND(G7-H7,0)) -> 335 | N7: =IF(COUNTIF(B7,""),,IF(J7,J7*100,PressureAltitude(I7,T7))) -> 1627 | O7: =IF(COUNTIF(B7,""),,IF(J7,DensityAltitude(J7*100,IsaDeviation(V7,U7)),DensityAltitude(PressureAltitude(I7,T7),IsaDeviation(PressureAltitude(V7,T7),U7)))) -> 2773.8952 | P7: =IF(COUNTIF(B7,""),,IF(J7,TrueAltitude(IndicatedAltitude(J7*100,T7),IsaDeviation(V7,U7)),TrueAltitude(I7,IsaDeviation(V7,U7)))) -> 1822.48 | Q7: =IF(COUNTIF(B7,""),,3000+L7) -> 3536 | R7: =IF(COUNTIF(B7,""),,MinimalFlightLevel(Q7,T7,M7)) -> 45 | S7: =IF(COUNTIF(B7,""),,TransitionLevel(Q7,T7)) -> 35 | T7: =IF(COUNTIF(B7,""),,LOG!Q$25) -> 1023 | U7: =IF(COUNTIF(B7,""),,LOG!Q$26) -> 25 | V7: =IF(COUNTIF(B7,""),,LOG!Q$27) -> 100 | W7: =IF(COUNTIF(B7,""),,SWITCH(WindMode,"Detailed",WINTEM!F7,"Average",AverageWindSpeed,"Manual",ManualWindSpeed)) -> 15 | X7: =IF(COUNTIF(B7,""),,SWITCH(WindMode,"Detailed",WINTEM!G7,"Average",AverageWindDirection,"Manual",ManualWindDirection)) -> 336 | Y7: =IF(COUNTIF(B7,""),,Z7+0) -> 98.080692 | Z7: =IF(COUNTIF(B7,""),,IF(J7,CorrectedAirSpeed(IndicatedAltitude(J7,T7),AB7,IsaDeviation(PressureAltitude(V7,T7),U7)),CorrectedAirSpeed(I7,AB7,IsaDeviation(PressureAltitude(V7,T7),U7)))) -> 98.080692 | AA7: =IF(COUNTIF(B7,""),,LOG!W$26) -> 0.6 | AB7: =IF(COUNTIF(B7,""),,60/AA7) -> 100 | AC7: =IF(COUNTIF(B7,""),,AB7*COS(RADIANS(AD7))-(W7*COS(RADIANS(M7-X7)))) -> 85.001942 | AD7: =IF(COUNTIF(B7,""),,DEGREES(ASIN(W7/AB7*SIN(RADIANS(M7-X7))))) -> -0.14999256 | AE7: =IF(COUNTIF(B7,""),,PERFORMANCE!H58) -> 13.280135 | AF7: =IF(COUNTIF(B7,""),,MOD(M7-AD7,360)) -> 335.14999 | AG7: =IF(COUNTIF(B7,""),,F7*60/AB7) -> 9.72 | AH7: =IF(COUNTIF(B7,""),,F7*60/AC7) -> 11.435033 | AI7: =IF(COUNTIF(B7,""),,AE7/60*AG7) -> 2.1513819 | AJ7: =IF(COUNTIF(B7,""),,AE7/60*AH7) -> 2.5309797 | AK7: =IF(COUNTIF(B7,""),,ROUND(ReqFuel(CARBURANT!G$20,CARBURANT!G$21,CARBURANT!G$22,CARBURANT!G$23,SUM(AH$2:AH7)),2)) -> 0.3 | AL7: =IF(COUNTIF(B7,""),,IF(COUNTIF(B8,""),AL6+AJ7+LOG!E$28,AL6+AJ7)) -> 13.341632
A8: =IF(COUNTIF(B8,""),,B7) | C8: =IF(COUNTIF(B8,""),,IF(COUNTIF(B9,""),C7+AH8/1440+LOG!D$28,C7+AH8/1440)) | D8: =IF(COUNTIF(B8,""),,C8) | E8: =IF(COUNTIF(B8,""),,E7+(D8-D7)*24) | F8: =IF(COUNTIF(B8,""),,ROUND(CONVERT(Distance(VLOOKUP(A8,WAYPOINTS!A:C,2,FALSE()),VLOOKUP(A8,WAYPOINTS!A:C,3,FALSE()),VLOOKUP(B8,WAYPOINTS!A:C,2,FALSE()),VLOOKUP(B8,WAYPOINTS!A:C,3,FALSE())),"m","Nmi"),1)) | G8: =IF(COUNTIF(B8,""),,MOD(Bearing(VLOOKUP(A8,WAYPOINTS!A:C,2,FALSE()),VLOOKUP(A8,WAYPOINTS!A:C,3,FALSE()),VLOOKUP(B8,WAYPOINTS!A:C,2,FALSE()),VLOOKUP(B8,WAYPOINTS!A:C,3,FALSE())),360)) | H8: =IFERROR(__xludf.DUMMYFUNCTION("IF(COUNTIF(B8,""""),,ROUND(SUBSTITUTE(IMPORTXML(""https://www.ngdc.noaa.gov/geomag-web/calculators/calculateDeclination?lat1=""&SUBSTITUTE(VLOOKUP(A8,WAYPOINTS!A:C,2,FALSE()),"","",""."")&""&lon1=""&SUBSTITUTE(VLOOKUP(A8,WAYPOINTS!A:C,3,FALSE()),"","",""."&""")&""&key=zNEw7&resultFormat=xml"",""//declination""),""."","",""),2))"),"") | K8: =IF(COUNTIF(B8,""),,ROUND(L8+1000,-2)) | L8: =IF(COUNTIF(B8,""),,ROUND(CONVERT(getElevation(AVERAGE(VLOOKUP(A8,WAYPOINTS!A:C,2,FALSE()),VLOOKUP(B8,WAYPOINTS!A:C,2,FALSE())),AVERAGE(VLOOKUP(A8,WAYPOINTS!A:C,3,FALSE()),VLOOKUP(B8,WAYPOINTS!A:C,3,FALSE()))),"m","ft"),0)) | M8: =IF(COUNTIF(B8,""),,ROUND(G8-H8,0)) | N8: =IF(COUNTIF(B8,""),,IF(J8,J8*100,PressureAltitude(I8,T8))) | O8: =IF(COUNTIF(B8,""),,IF(J8,DensityAltitude(J8*100,IsaDeviation(V8,U8)),DensityAltitude(PressureAltitude(I8,T8),IsaDeviation(PressureAltitude(V8,T8),U8)))) | P8: =IF(COUNTIF(B8,""),,IF(J8,TrueAltitude(IndicatedAltitude(J8*100,T8),IsaDeviation(V8,U8)),TrueAltitude(I8,IsaDeviation(V8,U8)))) | Q8: =IF(COUNTIF(B8,""),,3000+L8) | R8: =IF(COUNTIF(B8,""),,MinimalFlightLevel(Q8,T8,M8)) | S8: =IF(COUNTIF(B8,""),,TransitionLevel(Q8,T8)) | T8: =IF(COUNTIF(B8,""),,LOG!Q$25) | U8: =IF(COUNTIF(B8,""),,LOG!Q$26) | V8: =IF(COUNTIF(B8,""),,LOG!Q$27) | W8: =IF(COUNTIF(B8,""),,SWITCH(WindMode,"Detailed",WINTEM!F8,"Average",AverageWindSpeed,"Manual",ManualWindSpeed)) | X8: =IF(COUNTIF(B8,""),,SWITCH(WindMode,"Detailed",WINTEM!G8,"Average",AverageWindDirection,"Manual",ManualWindDirection)) | Y8: =IF(COUNTIF(B8,""),,Z8+0) | Z8: =IF(COUNTIF(B8,""),,IF(J8,CorrectedAirSpeed(IndicatedAltitude(J8,T8),AB8,IsaDeviation(PressureAltitude(V8,T8),U8)),CorrectedAirSpeed(I8,AB8,IsaDeviation(PressureAltitude(V8,T8),U8)))) | AA8: =IF(COUNTIF(B8,""),,LOG!W$26) | AB8: =IF(COUNTIF(B8,""),,60/AA8) | AC8: =IF(COUNTIF(B8,""),,AB8*COS(RADIANS(AD8))-(W8*COS(RADIANS(M8-X8)))) | AD8: =IF(COUNTIF(B8,""),,DEGREES(ASIN(W8/AB8*SIN(RADIANS(M8-X8))))) | AE8: =IF(COUNTIF(B8,""),,PERFORMANCE!H59) | AF8: =IF(COUNTIF(B8,""),,MOD(M8-AD8,360)) | AG8: =IF(COUNTIF(B8,""),,F8*60/AB8) | AH8: =IF(COUNTIF(B8,""),,F8*60/AC8) | AI8: =IF(COUNTIF(B8,""),,AE8/60*AG8) | AJ8: =IF(COUNTIF(B8,""),,AE8/60*AH8) | AK8: =IF(COUNTIF(B8,""),,ROUND(ReqFuel(CARBURANT!G$20,CARBURANT!G$21,CARBURANT!G$22,CARBURANT!G$23,SUM(AH$2:AH8)),2)) | AL8: =IF(COUNTIF(B8,""),,IF(COUNTIF(B9,""),AL7+AJ8+LOG!E$28,AL7+AJ8))
A9: =IF(COUNTIF(B9,""),,B8) | C9: =IF(COUNTIF(B9,""),,IF(COUNTIF(B10,""),C8+AH9/1440+LOG!D$28,C8+AH9/1440)) | D9: =IF(COUNTIF(B9,""),,C9) | E9: =IF(COUNTIF(B9,""),,E8+(D9-D8)*24) | F9: =IF(COUNTIF(B9,""),,ROUND(CONVERT(Distance(VLOOKUP(A9,WAYPOINTS!A:C,2,FALSE()),VLOOKUP(A9,WAYPOINTS!A:C,3,FALSE()),VLOOKUP(B9,WAYPOINTS!A:C,2,FALSE()),VLOOKUP(B9,WAYPOINTS!A:C,3,FALSE())),"m","Nmi"),1)) | G9: =IF(COUNTIF(B9,""),,MOD(Bearing(VLOOKUP(A9,WAYPOINTS!A:C,2,FALSE()),VLOOKUP(A9,WAYPOINTS!A:C,3,FALSE()),VLOOKUP(B9,WAYPOINTS!A:C,2,FALSE()),VLOOKUP(B9,WAYPOINTS!A:C,3,FALSE())),360)) | H9: =IFERROR(__xludf.DUMMYFUNCTION("IF(COUNTIF(B9,""""),,ROUND(SUBSTITUTE(IMPORTXML(""https://www.ngdc.noaa.gov/geomag-web/calculators/calculateDeclination?lat1=""&SUBSTITUTE(VLOOKUP(A9,WAYPOINTS!A:C,2,FALSE()),"","",""."")&""&lon1=""&SUBSTITUTE(VLOOKUP(A9,WAYPOINTS!A:C,3,FALSE()),"","",""."&""")&""&key=zNEw7&resultFormat=xml"",""//declination""),""."","",""),2))"),"") | K9: =IF(COUNTIF(B9,""),,ROUND(L9+1000,-2)) | L9: =IF(COUNTIF(B9,""),,ROUND(CONVERT(getElevation(AVERAGE(VLOOKUP(A9,WAYPOINTS!A:C,2,FALSE()),VLOOKUP(B9,WAYPOINTS!A:C,2,FALSE())),AVERAGE(VLOOKUP(A9,WAYPOINTS!A:C,3,FALSE()),VLOOKUP(B9,WAYPOINTS!A:C,3,FALSE()))),"m","ft"),0)) | M9: =IF(COUNTIF(B9,""),,ROUND(G9-H9,0)) | N9: =IF(COUNTIF(B9,""),,IF(J9,J9*100,PressureAltitude(I9,T9))) | O9: =IF(COUNTIF(B9,""),,IF(J9,DensityAltitude(J9*100,IsaDeviation(V9,U9)),DensityAltitude(PressureAltitude(I9,T9),IsaDeviation(PressureAltitude(V9,T9),U9)))) | P9: =IF(COUNTIF(B9,""),,IF(J9,TrueAltitude(IndicatedAltitude(J9*100,T9),IsaDeviation(V9,U9)),TrueAltitude(I9,IsaDeviation(V9,U9)))) | Q9: =IF(COUNTIF(B9,""),,3000+L9) | R9: =IF(COUNTIF(B9,""),,MinimalFlightLevel(Q9,T9,M9)) | S9: =IF(COUNTIF(B9,""),,TransitionLevel(Q9,T9)) | T9: =IF(COUNTIF(B9,""),,LOG!Q$25) | U9: =IF(COUNTIF(B9,""),,LOG!Q$26) | V9: =IF(COUNTIF(B9,""),,LOG!Q$27) | W9: =IF(COUNTIF(B9,""),,SWITCH(WindMode,"Detailed",WINTEM!F9,"Average",AverageWindSpeed,"Manual",ManualWindSpeed)) | X9: =IF(COUNTIF(B9,""),,SWITCH(WindMode,"Detailed",WINTEM!G9,"Average",AverageWindDirection,"Manual",ManualWindDirection)) | Y9: =IF(COUNTIF(B9,""),,Z9+0) | Z9: =IF(COUNTIF(B9,""),,IF(J9,CorrectedAirSpeed(IndicatedAltitude(J9,T9),AB9,IsaDeviation(PressureAltitude(V9,T9),U9)),CorrectedAirSpeed(I9,AB9,IsaDeviation(PressureAltitude(V9,T9),U9)))) | AA9: =IF(COUNTIF(B9,""),,LOG!W$26) | AB9: =IF(COUNTIF(B9,""),,60/AA9) | AC9: =IF(COUNTIF(B9,""),,AB9*COS(RADIANS(AD9))-(W9*COS(RADIANS(M9-X9)))) | AD9: =IF(COUNTIF(B9,""),,DEGREES(ASIN(W9/AB9*SIN(RADIANS(M9-X9))))) | AE9: =IF(COUNTIF(B9,""),,PERFORMANCE!H60) | AF9: =IF(COUNTIF(B9,""),,MOD(M9-AD9,360)) | AG9: =IF(COUNTIF(B9,""),,F9*60/AB9) | AH9: =IF(COUNTIF(B9,""),,F9*60/AC9) | AI9: =IF(COUNTIF(B9,""),,AE9/60*AG9) | AJ9: =IF(COUNTIF(B9,""),,AE9/60*AH9) | AK9: =IF(COUNTIF(B9,""),,ROUND(ReqFuel(CARBURANT!G$20,CARBURANT!G$21,CARBURANT!G$22,CARBURANT!G$23,SUM(AH$2:AH9)),2)) | AL9: =IF(COUNTIF(B9,""),,IF(COUNTIF(B10,""),AL8+AJ9+LOG!E$28,AL8+AJ9))
A10: =IF(COUNTIF(B10,""),,B9) | C10: =IF(COUNTIF(B10,""),,IF(COUNTIF(B11,""),C9+AH10/1440+LOG!D$28,C9+AH10/1440)) | D10: =IF(COUNTIF(B10,""),,C10) | E10: =IF(COUNTIF(B10,""),,E9+(D10-D9)*24) | F10: =IF(COUNTIF(B10,""),,ROUND(CONVERT(Distance(VLOOKUP(A10,WAYPOINTS!A:C,2,FALSE()),VLOOKUP(A10,WAYPOINTS!A:C,3,FALSE()),VLOOKUP(B10,WAYPOINTS!A:C,2,FALSE()),VLOOKUP(B10,WAYPOINTS!A:C,3,FALSE())),"m","Nmi"),1)) | G10: =IF(COUNTIF(B10,""),,MOD(Bearing(VLOOKUP(A10,WAYPOINTS!A:C,2,FALSE()),VLOOKUP(A10,WAYPOINTS!A:C,3,FALSE()),VLOOKUP(B10,WAYPOINTS!A:C,2,FALSE()),VLOOKUP(B10,WAYPOINTS!A:C,3,FALSE())),360)) | H10: =IFERROR(__xludf.DUMMYFUNCTION("IF(COUNTIF(B10,""""),,ROUND(SUBSTITUTE(IMPORTXML(""https://www.ngdc.noaa.gov/geomag-web/calculators/calculateDeclination?lat1=""&SUBSTITUTE(VLOOKUP(A10,WAYPOINTS!A:C,2,FALSE()),"","",""."")&""&lon1=""&SUBSTITUTE(VLOOKUP(A10,WAYPOINTS!A:C,3,FALSE()),"","","&"""."")&""&key=zNEw7&resultFormat=xml"",""//declination""),""."","",""),2))"),"") | K10: =IF(COUNTIF(B10,""),,ROUND(L10+1000,-2)) | L10: =IF(COUNTIF(B10,""),,ROUND(CONVERT(getElevation(AVERAGE(VLOOKUP(A10,WAYPOINTS!A:C,2,FALSE()),VLOOKUP(B10,WAYPOINTS!A:C,2,FALSE())),AVERAGE(VLOOKUP(A10,WAYPOINTS!A:C,3,FALSE()),VLOOKUP(B10,WAYPOINTS!A:C,3,FALSE()))),"m","ft"),0)) | M10: =IF(COUNTIF(B10,""),,ROUND(G10-H10,0)) | N10: =IF(COUNTIF(B10,""),,IF(J10,J10*100,PressureAltitude(I10,T10))) | O10: =IF(COUNTIF(B10,""),,IF(J10,DensityAltitude(J10*100,IsaDeviation(V10,U10)),DensityAltitude(PressureAltitude(I10,T10),IsaDeviation(PressureAltitude(V10,T10),U10)))) | P10: =IF(COUNTIF(B10,""),,IF(J10,TrueAltitude(IndicatedAltitude(J10*100,T10),IsaDeviation(V10,U10)),TrueAltitude(I10,IsaDeviation(V10,U10)))) | Q10: =IF(COUNTIF(B10,""),,3000+L10) | R10: =IF(COUNTIF(B10,""),,MinimalFlightLevel(Q10,T10,M10)) | S10: =IF(COUNTIF(B10,""),,TransitionLevel(Q10,T10)) | T10: =IF(COUNTIF(B10,""),,LOG!Q$25) | U10: =IF(COUNTIF(B10,""),,LOG!Q$26) | V10: =IF(COUNTIF(B10,""),,LOG!Q$27) | W10: =IF(COUNTIF(B10,""),,SWITCH(WindMode,"Detailed",WINTEM!F10,"Average",AverageWindSpeed,"Manual",ManualWindSpeed)) | X10: =IF(COUNTIF(B10,""),,SWITCH(WindMode,"Detailed",WINTEM!G10,"Average",AverageWindDirection,"Manual",ManualWindDirection)) | Y10: =IF(COUNTIF(B10,""),,Z10+0) | Z10: =IF(COUNTIF(B10,""),,IF(J10,CorrectedAirSpeed(IndicatedAltitude(J10,T10),AB10,IsaDeviation(PressureAltitude(V10,T10),U10)),CorrectedAirSpeed(I10,AB10,IsaDeviation(PressureAltitude(V10,T10),U10)))) | AA10: =IF(COUNTIF(B10,""),,LOG!W$26) | AB10: =IF(COUNTIF(B10,""),,60/AA10) | AC10: =IF(COUNTIF(B10,""),,AB10*COS(RADIANS(AD10))-(W10*COS(RADIANS(M10-X10)))) | AD10: =IF(COUNTIF(B10,""),,DEGREES(ASIN(W10/AB10*SIN(RADIANS(M10-X10))))) | AE10: =IF(COUNTIF(B10,""),,PERFORMANCE!H61) | AF10: =IF(COUNTIF(B10,""),,MOD(M10-AD10,360)) | AG10: =IF(COUNTIF(B10,""),,F10*60/AB10) | AH10: =IF(COUNTIF(B10,""),,F10*60/AC10) | AI10: =IF(COUNTIF(B10,""),,AE10/60*AG10) | AJ10: =IF(COUNTIF(B10,""),,AE10/60*AH10) | AK10: =IF(COUNTIF(B10,""),,ROUND(ReqFuel(CARBURANT!G$20,CARBURANT!G$21,CARBURANT!G$22,CARBURANT!G$23,SUM(AH$2:AH10)),2)) | AL10: =IF(COUNTIF(B10,""),,IF(COUNTIF(B11,""),AL9+AJ10+LOG!E$28,AL9+AJ10))
A11: =IF(COUNTIF(B11,""),,B10) | C11: =IF(COUNTIF(B11,""),,IF(COUNTIF(B12,""),C10+AH11/1440+LOG!D$28,C10+AH11/1440)) | D11: =IF(COUNTIF(B11,""),,C11) | E11: =IF(COUNTIF(B11,""),,E10+(D11-D10)*24) | F11: =IF(COUNTIF(B11,""),,ROUND(CONVERT(Distance(VLOOKUP(A11,WAYPOINTS!A:C,2,FALSE()),VLOOKUP(A11,WAYPOINTS!A:C,3,FALSE()),VLOOKUP(B11,WAYPOINTS!A:C,2,FALSE()),VLOOKUP(B11,WAYPOINTS!A:C,3,FALSE())),"m","Nmi"),1)) | G11: =IF(COUNTIF(B11,""),,MOD(Bearing(VLOOKUP(A11,WAYPOINTS!A:C,2,FALSE()),VLOOKUP(A11,WAYPOINTS!A:C,3,FALSE()),VLOOKUP(B11,WAYPOINTS!A:C,2,FALSE()),VLOOKUP(B11,WAYPOINTS!A:C,3,FALSE())),360)) | H11: =IFERROR(__xludf.DUMMYFUNCTION("IF(COUNTIF(B11,""""),,ROUND(SUBSTITUTE(IMPORTXML(""https://www.ngdc.noaa.gov/geomag-web/calculators/calculateDeclination?lat1=""&SUBSTITUTE(VLOOKUP(A11,WAYPOINTS!A:C,2,FALSE()),"","",""."")&""&lon1=""&SUBSTITUTE(VLOOKUP(A11,WAYPOINTS!A:C,3,FALSE()),"","","&"""."")&""&key=zNEw7&resultFormat=xml"",""//declination""),""."","",""),2))"),"") | K11: =IF(COUNTIF(B11,""),,ROUND(L11+1000,-2)) | L11: =IF(COUNTIF(B11,""),,ROUND(CONVERT(getElevation(AVERAGE(VLOOKUP(A11,WAYPOINTS!A:C,2,FALSE()),VLOOKUP(B11,WAYPOINTS!A:C,2,FALSE())),AVERAGE(VLOOKUP(A11,WAYPOINTS!A:C,3,FALSE()),VLOOKUP(B11,WAYPOINTS!A:C,3,FALSE()))),"m","ft"),0)) | M11: =IF(COUNTIF(B11,""),,ROUND(G11-H11,0)) | N11: =IF(COUNTIF(B11,""),,IF(J11,J11*100,PressureAltitude(I11,T11))) | O11: =IF(COUNTIF(B11,""),,IF(J11,DensityAltitude(J11*100,IsaDeviation(V11,U11)),DensityAltitude(PressureAltitude(I11,T11),IsaDeviation(PressureAltitude(V11,T11),U11)))) | P11: =IF(COUNTIF(B11,""),,IF(J11,TrueAltitude(IndicatedAltitude(J11*100,T11),IsaDeviation(V11,U11)),TrueAltitude(I11,IsaDeviation(V11,U11)))) | Q11: =IF(COUNTIF(B11,""),,3000+L11) | R11: =IF(COUNTIF(B11,""),,MinimalFlightLevel(Q11,T11,M11)) | S11: =IF(COUNTIF(B11,""),,TransitionLevel(Q11,T11)) | T11: =IF(COUNTIF(B11,""),,LOG!Q$25) | U11: =IF(COUNTIF(B11,""),,LOG!Q$26) | V11: =IF(COUNTIF(B11,""),,LOG!Q$27) | W11: =IF(COUNTIF(B11,""),,SWITCH(WindMode,"Detailed",WINTEM!F11,"Average",AverageWindSpeed,"Manual",ManualWindSpeed)) | X11: =IF(COUNTIF(B11,""),,SWITCH(WindMode,"Detailed",WINTEM!G11,"Average",AverageWindDirection,"Manual",ManualWindDirection)) | Y11: =IF(COUNTIF(B11,""),,Z11+0) | Z11: =IF(COUNTIF(B11,""),,IF(J11,CorrectedAirSpeed(IndicatedAltitude(J11,T11),AB11,IsaDeviation(PressureAltitude(V11,T11),U11)),CorrectedAirSpeed(I11,AB11,IsaDeviation(PressureAltitude(V11,T11),U11)))) | AA11: =IF(COUNTIF(B11,""),,LOG!W$26) | AB11: =IF(COUNTIF(B11,""),,60/AA11) | AC11: =IF(COUNTIF(B11,""),,AB11*COS(RADIANS(AD11))-(W11*COS(RADIANS(M11-X11)))) | AD11: =IF(COUNTIF(B11,""),,DEGREES(ASIN(W11/AB11*SIN(RADIANS(M11-X11))))) | AE11: =IF(COUNTIF(B11,""),,PERFORMANCE!H62) | AF11: =IF(COUNTIF(B11,""),,MOD(M11-AD11,360)) | AG11: =IF(COUNTIF(B11,""),,F11*60/AB11) | AH11: =IF(COUNTIF(B11,""),,F11*60/AC11) | AI11: =IF(COUNTIF(B11,""),,AE11/60*AG11) | AJ11: =IF(COUNTIF(B11,""),,AE11/60*AH11) | AK11: =IF(COUNTIF(B11,""),,ROUND(ReqFuel(CARBURANT!G$20,CARBURANT!G$21,CARBURANT!G$22,CARBURANT!G$23,SUM(AH$2:AH11)),2)) | AL11: =IF(COUNTIF(B11,""),,IF(COUNTIF(B12,""),AL10+AJ11+LOG!E$28,AL10+AJ11))
A12: =IF(COUNTIF(B12,""),,B11) | C12: =IF(COUNTIF(B12,""),,IF(COUNTIF(B13,""),C11+AH12/1440+LOG!D$28,C11+AH12/1440)) | D12: =IF(COUNTIF(B12,""),,C12) | E12: =IF(COUNTIF(B12,""),,E11+(D12-D11)*24) | F12: =IF(COUNTIF(B12,""),,ROUND(CONVERT(Distance(VLOOKUP(A12,WAYPOINTS!A:C,2,FALSE()),VLOOKUP(A12,WAYPOINTS!A:C,3,FALSE()),VLOOKUP(B12,WAYPOINTS!A:C,2,FALSE()),VLOOKUP(B12,WAYPOINTS!A:C,3,FALSE())),"m","Nmi"),1)) | G12: =IF(COUNTIF(B12,""),,MOD(Bearing(VLOOKUP(A12,WAYPOINTS!A:C,2,FALSE()),VLOOKUP(A12,WAYPOINTS!A:C,3,FALSE()),VLOOKUP(B12,WAYPOINTS!A:C,2,FALSE()),VLOOKUP(B12,WAYPOINTS!A:C,3,FALSE())),360)) | H12: =IFERROR(__xludf.DUMMYFUNCTION("IF(COUNTIF(B12,""""),,ROUND(SUBSTITUTE(IMPORTXML(""https://www.ngdc.noaa.gov/geomag-web/calculators/calculateDeclination?lat1=""&SUBSTITUTE(VLOOKUP(A12,WAYPOINTS!A:C,2,FALSE()),"","",""."")&""&lon1=""&SUBSTITUTE(VLOOKUP(A12,WAYPOINTS!A:C,3,FALSE()),"","","&"""."")&""&key=zNEw7&resultFormat=xml"",""//declination""),""."","",""),2))"),"") | K12: =IF(COUNTIF(B12,""),,ROUND(L12+1000,-2)) | L12: =IF(COUNTIF(B12,""),,ROUND(CONVERT(getElevation(AVERAGE(VLOOKUP(A12,WAYPOINTS!A:C,2,FALSE()),VLOOKUP(B12,WAYPOINTS!A:C,2,FALSE())),AVERAGE(VLOOKUP(A12,WAYPOINTS!A:C,3,FALSE()),VLOOKUP(B12,WAYPOINTS!A:C,3,FALSE()))),"m","ft"),0)) | M12: =IF(COUNTIF(B12,""),,ROUND(G12-H12,0)) | N12: =IF(COUNTIF(B12,""),,IF(J12,J12*100,PressureAltitude(I12,T12))) | O12: =IF(COUNTIF(B12,""),,IF(J12,DensityAltitude(J12*100,IsaDeviation(V12,U12)),DensityAltitude(PressureAltitude(I12,T12),IsaDeviation(PressureAltitude(V12,T12),U12)))) | P12: =IF(COUNTIF(B12,""),,IF(J12,TrueAltitude(IndicatedAltitude(J12*100,T12),IsaDeviation(V12,U12)),TrueAltitude(I12,IsaDeviation(V12,U12)))) | Q12: =IF(COUNTIF(B12,""),,3000+L12) | R12: =IF(COUNTIF(B12,""),,MinimalFlightLevel(Q12,T12,M12)) | S12: =IF(COUNTIF(B12,""),,TransitionLevel(Q12,T12)) | T12: =IF(COUNTIF(B12,""),,LOG!Q$25) | U12: =IF(COUNTIF(B12,""),,LOG!Q$26) | V12: =IF(COUNTIF(B12,""),,LOG!Q$27) | W12: =IF(COUNTIF(B12,""),,SWITCH(WindMode,"Detailed",WINTEM!F12,"Average",AverageWindSpeed,"Manual",ManualWindSpeed)) | X12: =IF(COUNTIF(B12,""),,SWITCH(WindMode,"Detailed",WINTEM!G12,"Average",AverageWindDirection,"Manual",ManualWindDirection)) | Y12: =IF(COUNTIF(B12,""),,Z12+0) | Z12: =IF(COUNTIF(B12,""),,IF(J12,CorrectedAirSpeed(IndicatedAltitude(J12,T12),AB12,IsaDeviation(PressureAltitude(V12,T12),U12)),CorrectedAirSpeed(I12,AB12,IsaDeviation(PressureAltitude(V12,T12),U12)))) | AA12: =IF(COUNTIF(B12,""),,LOG!W$26) | AB12: =IF(COUNTIF(B12,""),,60/AA12) | AC12: =IF(COUNTIF(B12,""),,AB12*COS(RADIANS(AD12))-(W12*COS(RADIANS(M12-X12)))) | AD12: =IF(COUNTIF(B12,""),,DEGREES(ASIN(W12/AB12*SIN(RADIANS(M12-X12))))) | AE12: =IF(COUNTIF(B12,""),,PERFORMANCE!H63) | AF12: =IF(COUNTIF(B12,""),,MOD(M12-AD12,360)) | AG12: =IF(COUNTIF(B12,""),,F12*60/AB12) | AH12: =IF(COUNTIF(B12,""),,F12*60/AC12) | AI12: =IF(COUNTIF(B12,""),,AE12/60*AG12) | AJ12: =IF(COUNTIF(B12,""),,AE12/60*AH12) | AK12: =IF(COUNTIF(B12,""),,ROUND(ReqFuel(CARBURANT!G$20,CARBURANT!G$21,CARBURANT!G$22,CARBURANT!G$23,SUM(AH$2:AH12)),2)) | AL12: =IF(COUNTIF(B12,""),,IF(COUNTIF(B13,""),AL11+AJ12+LOG!E$28,AL11+AJ12))
